Workbook

Sheet Вводные
A1: ВВОДНЫЕ ДАННЫЕ
A3: Параметр | B3: Значение | C3: Ед. | D3: Комментарий
A4: Название проекта | B4: Жилой проект | D4: Рабочее название
A5: Регион | B5: Якутия | D5: Пользовательский ввод
A6: Класс жилья | B6: Комфорт | D6: Пользовательский ввод
A7: Дата старта проекта | B7: 46054 | C7: дата | D7: Начало модели
A8: Срок строительства | B8: 18 | C8: мес | D8: До ввода
A9: Срок продаж | B9: 16 | C9: мес | D9: Период продаж
A10: GBA | B10: 10795.3 | C10: м2 | D10: Общая площадь здания
A11: GSA | B11: 7860.32 | C11: м2 | D11: Продаваемая площадь
A12: Количество машиномест | B12: 6 | C12: шт | D12: Машиноместа
A13: Цена продажи квартир | B13: 175000 | C13: руб/м2 | D13: Актуализировано по рынку Якутска
A14: Цена машиноместа | B14: 1600000 | C14: руб/шт | D14: Актуализировано по рынку машиномест
A15: Рост цен продаж | B15: 0.08 | C15: % | D15: Годовой рост
A16: Инфляция строительства | B16: 0.076 | C16: % | D16: Годовой рост ставок
A17: Коэффициент региона | B17: 1 | C17: x | D17: Региональная корректировка
A18: Минимальная доля собственных средств | B18: 0.1503 | C18: % | D18: По кредитному договору
... A26: Ставка I(v) >130% | B26: 0.0001 | C26: % | D26: По кредитному договору
A27: Дата окончания отсрочки процентов | B27: =EDATE(B7,B8-1) -> 46569 | C27: дата | D27: Автоматически = месяц ввода (от даты старта и срока строительства)
A28: Дата полного погашения кредита | B28: =EDATE(B7,B8-1) -> 46569 | C28: дата | D28: Автоматически = месяц ввода / закрытия кредита
A29: Целевой DSCR | B29: 1.2 | C29: x | D29: Контрольный ориентир
A31: СТАВКИ ПО ГЛАВЕ 1
A32: 1.1.1 Стоимость покупки права / доли / зданий | C32: руб/м2 GSA | D32: Укрупненно
A33: 1.1.2 Арендные платежи / земельный налог | C33: руб/м2 GSA | D33: Укрупненно
A34: 1.2 Изменение ВРИ | C34: руб/м2 GSA | D34: Укрупненно
A35: 1.3 Прочие затраты на содержание ЗУ | C35: руб/м2 GSA | D35: Укрупненно
A37: СТАВКИ ПО ГЛАВЕ 2
A38: 2.1 Подготовительный период | B38: 1800 | C38: руб/м2 GSA | D38: Откалибровано под Якутию / апрель 2026
A39: 2.2.1 Земляные работы | B39: 1800 | C39: руб/м2 GBA | D39: Укрупненно
A40: 2.2.2 Фундамент / сваи / ограждение котлована | B40: 7650 | C40: руб/м2 GBA | D40: Укрупненно
A41: 2.2.3 Подземная часть | B41: 0 | C41: руб/м2 GBA | D41: Укрупненно
A42: 2.2.4 Надземная часть | B42: 19900 | C42: руб/м2 GBA | D42: Укрупненно
A43: 2.2.5 Ограждающие конструкции / кровля | B43: 9700 | C43: руб/м2 GBA | D43: Укрупненно
A44: 2.2.6 Отделка МОП и техпомещений | B44: 6050 | C44: руб/м2 GBA | D44: Укрупненно
A45: 2.2.7 Отделка реализуемых площадей | B45: 0 | C45: руб/м2 GSA | D45: Если есть чистовая
A46: 2.2.8 Наружная отделка / проемы | B46: 8600 | C46: руб/м2 GBA | D46: Укрупненно
A47: 2.3.1 Вертикальный транспорт | B47: 520 | C47: руб/м2 GBA | D47: Укрупненно
A48: 2.3.2 Сантехнические системы | B48: 4140 | C48: руб/м2 GBA | D48: Укрупненно
A49: 2.3.3 Отопление / ИТП | B49: 2470 | C49: руб/м2 GBA | D49: Укрупненно
... A61: 2.8 Резерв на непредвиденные | B61: 0.05 | C61: % | D61: % от главы 2 до резерва
...

Sheet Структура_затрат
A1: ФИНАНСОВАЯ МОДЕЛЬ / СТРУКТУРА ЗАТРАТ
J2: Разбивка СМР | K2: Материалы | L2: Работы
A3: Глава | B3: Код | C3: Статья | D3: База | E3: Ед. | F3: Ставка | G3: Коэфф. | H3: Сумма | I3: Примечание | J3: Материалы, % | K3: Материалы | L3: Работы
A4: 1 | B4: 1.1.1 | C4: Стоимость покупки права / доли / зданий | D4: =Вводные!$B11 -> 7860.32 | E4: м2 GSA | G4: =Вводные!$B17 -> 1 | H4: =D4*F4*G4 -> 0
A5: 1 | B5: 1.1.2 | C5: Арендные платежи / земельный налог | D5: =Вводные!$B11 -> 7860.32 | E5: м2 GSA | G5: =Вводные!$B17 -> 1 | H5: =D5*F5*G5 -> 0
A6: 1 | B6: 1.2 | C6: Изменение ВРИ | D6: =Вводные!$B11 -> 7860.32 | E6: м2 GSA | G6: =Вводные!$B17 -> 1 | H6: =D6*F6*G6 -> 0
A7: 1 | B7: 1.3 | C7: Прочие затраты на содержание ЗУ | D7: =Вводные!$B11 -> 7860.32 | E7: м2 GSA | G7: =Вводные!$B17 -> 1 | H7: =D7*F7*G7 -> 0
C8: ИТОГО ГЛАВА 1 | H8: =SUM(H4:H7) -> 0
A9: 2 | B9: 2.1 | C9: Подготовительный период | D9: =Вводные!$B11 -> 7860.32 | E9: м2 GSA | F9: =Вводные!$B38 -> 1800 | G9: =Вводные!$B17 -> 1 | H9: =D9*F9*G9 -> 14148576 | J9: 0.35 | K9: =H9*J9 -> 4952001.6 | L9: =H9-K9 -> 9196574.4
A10: 2 | B10: 2.2.1 | C10: Земляные работы | D10: =Вводные!$B10 -> 10795.3 | E10: м2 GBA | F10: =Вводные!$B39 -> 1800 | G10: =Вводные!$B17 -> 1 | H10: =D10*F10*G10 -> 19431540 | J10: 0.3 | K10: =H10*J10 -> 5829462 | L10: =H10-K10 -> 13602078
A11: 2 | B11: 2.2.2 | C11: Фундаментная плита / свайное основание / ограждение котлована | D11: =Вводные!$B10 -> 10795.3 | E11: м2 GBA | F11: =Вводные!$B40 -> 7650 | G11: =Вводные!$B17 -> 1 | H11: =D11*F11*G11 -> 82584045 | J11: 0.6 | K11: =H11*J11 -> 49550427 | L11: =H11-K11 -> 33033618
A12: 2 | B12: 2.2.3 | C12: Устройство несущих конструкций подземной части | D12: =Вводные!$B10 -> 10795.3 | E12: м2 GBA | F12: =Вводные!$B41 -> 0 | G12: =Вводные!$B17 -> 1 | H12: =D12*F12*G12 -> 0 | J12: 0.6 | K12: =H12*J12 -> 0 | L12: =H12-K12 -> 0
A13: 2 | B13: 2.2.4 | C13: Устройство несущих конструкций надземной части | D13: =Вводные!$B10 -> 10795.3 | E13: м2 GBA | F13: =Вводные!$B42 -> 19900 | G13: =Вводные!$B17 -> 1 | H13: =D13*F13*G13 -> 214826470 | J13: 0.65 | K13: =H13*J13 -> 1.3963721e+08 | L13: =H13-K13 -> 75189264
A14: 2 | B14: 2.2.5 | C14: Ограждающие конструкции / внутренние стены / кровля | D14: =Вводные!$B10 -> 10795.3 | E14: м2 GBA | F14: =Вводные!$B43 -> 9700 | G14: =Вводные!$B17 -> 1 | H14: =D14*F14*G14 -> 104714410 | J14: 0.7 | K14: =H14*J14 -> 73300087 | L14: =H14-K14 -> 31414323
A15: 2 | B15: 2.2.6 | C15: Внутренняя отделка МОП и техпомещений | D15: =Вводные!$B10 -> 10795.3 | E15: м2 GBA | F15: =Вводные!$B44 -> 6050 | G15: =Вводные!$B17 -> 1 | H15: =D15*F15*G15 -> 65311565 | J15: 0.6 | K15: =H15*J15 -> 39186939 | L15: =H15-K15 -> 26124626
A16: 2 | B16: 2.2.7 | C16: Отделка реализуемых площадей | D16: =Вводные!$B11 -> 7860.32 | E16: м2 GSA | F16: =Вводные!$B45 -> 0 | G16: =Вводные!$B17 -> 1 | H16: =D16*F16*G16 -> 0 | J16: 0.65 | K16: =H16*J16 -> 0 | L16: =H16-K16 -> 0
A17: 2 | B17: 2.2.8 | C17: Наружная отделка / заполнение проемов | D17: =Вводные!$B10 -> 10795.3 | E17: м2 GBA | F17: =Вводные!$B46 -> 8600 | G17: =Вводные!$B17 -> 1 | H17: =D17*F17*G17 -> 92839580 | J17: 0.75 | K17: =H17*J17 -> 69629685 | L17: =H17-K17 -> 23209895
A18: 2 | B18: 2.3.1 | C18: Вертикальный транспорт | D18: =Вводные!$B10 -> 10795.3 | E18: м2 GBA | F18: =Вводные!$B47 -> 520 | G18: =Вводные!$B17 -> 1 | H18: =D18*F18*G18 -> 5613556 | J18: 0.8 | K18: =H18*J18 -> 4490844.8 | L18: =H18-K18 -> 1122711.2
A19: 2 | B19: 2.3.2 | C19: Сантехнические системы | D19: =Вводные!$B10 -> 10795.3 | E19: м2 GBA | F19: =Вводные!$B48 -> 4140 | G19: =Вводные!$B17 -> 1 | H19: =D19*F19*G19 -> 44692542 | J19: 0.65 | K19: =H19*J19 -> 29050152 | L19: =H19-K19 -> 15642390
A20: 2 | B20: 2.3.3 | C20: Отопление / ИТП / узел учета | D20: =Вводные!$B10 -> 10795.3 | E20: м2 GBA | F20: =Вводные!$B49 -> 2470 | G20: =Вводные!$B17 -> 1 | H20: =D20*F20*G20 -> 26664391 | J20: 0.6 | K20: =H20*J20 -> 15998635 | L20: =H20-K20 -> 10665756
A21: 2 | B21: 2.3.4 | C21: Вентиляция / кондиционирование / дымоудаление | D21: =Вводные!$B10 -> 10795.3 | E21: м2 GBA | F21: =Вводные!$B50 -> 3420 | G21: =Вводные!$B17 -> 1 | H21: =D21*F21*G21 -> 36919926 | J21: 0.7 | K21: =H21*J21 -> 25843948 | L21: =H21-K21 -> 11075978
A22: 2 | B22: 2.3.5 | C22: Электроснабжение / электроосвещение / слаботочка | D22: =Вводные!$B10 -> 10795.3 | E22: м2 GBA | F22: =Вводные!$B51 -> 5330 | G22: =Вводные!$B17 -> 1 | H22: =D22*F22*G22 -> 57538949 | J22: 0.65 | K22: =H22*J22 -> 37400317 | L22: =H22-K22 -> 20138632
A23: 2 | B23: 2.3.6 | C23: Газоснабжение внутреннее | D23: =Вводные!$B10 -> 10795.3 | E23: м2 GBA | F23: =Вводные!$B52 -> 0 | G23: =Вводные!$B17 -> 1 | H23: =D23*F23*G23 -> 0 | J23: 0.7 | K23: =H23*J23 -> 0 | L23: =H23-K23 -> 0
A24: 2 | B24: 2.4.1 | C24: Наружное водоснабжение / ВЗУ / ТП | D24: =Вводные!$B11 -> 7860.32 | E24: м2 GSA | F24: =Вводные!$B53 -> 960 | G24: =Вводные!$B17 -> 1 | H24: =D24*F24*G24 -> 7545907.2 | J24: 0.6 | K24: =H24*J24 -> 4527544.3 | L24: =H24-K24 -> 3018362.9
A25: 2 | B25: 2.4.2 | C25: Наружные электросети / ТП / связь | D25: =Вводные!$B11 -> 7860.32 | E25: м2 GSA | F25: =Вводные!$B54 -> 1270 | G25: =Вводные!$B17 -> 1 | H25: =D25*F25*G25 -> 9982606.4 | J25: 0.7 | K25: =H25*J25 -> 6987824.5 | L25: =H25-K25 -> 2994781.9
A26: 2 | B26: 2.4.3 | C26: Наружное теплоснабжение / ЦТП / котельная | D26: =Вводные!$B11 -> 7860.32 | E26: м2 GSA | F26: =Вводные!$B55 -> 720 | G26: =Вводные!$B17 -> 1 | H26: =D26*F26*G26 -> 5659430.4 | J26: 0.65 | K26: =H26*J26 -> 3678629.8 | L26: =H26-K26 -> 1980800.6
A27: 2 | B27: 2.4.4 | C27: Бытовая и ливневая канализация | D27: =Вводные!$B11 -> 7860.32 | E27: м2 GSA | F27: =Вводные!$B56 -> 640 | G27: =Вводные!$B17 -> 1 | H27: =D27*F27*G27 -> 5030604.8 | J27: 0.6 | K27: =H27*J27 -> 3018362.9 | L27: =H27-K27 -> 2012241.9
A28: 2 | B28: 2.4.5 | C28: Наружное газоснабжение | D28: =Вводные!$B11 -> 7860.32 | E28: м2 GSA | F28: =Вводные!$B57 -> 0 | G28: =Вводные!$B17 -> 1 | H28: =D28*F28*G28 -> 0 | J28: 0.7 | K28: =H28*J28 -> 0 | L28: =H28-K28 -> 0
A29: 2 | B29: 2.5 | C29: Благоустройство и озеленение | D29: =Вводные!$B10 -> 10795.3 | E29: м2 GBA | F29: =Вводные!$B58 -> 2870 | G29: =Вводные!$B17 -> 1 | H29: =D29*F29*G29 -> 30982511 | J29: 0.5 | K29: =H29*J29 -> 15491255 | L29: =H29-K29 -> 15491255
A30: 2 | B30: 2.6 | C30: Служба заказчика-застройщика / охрана | D30: =SUM(H9:H29) -> 8.2448661e+08 | E30: руб | F30: =Вводные!$B59 -> 0.025 | G30: =1 -> 1 | H30: =D30*F30 -> 20612165
A31: 2 | B31: 2.7 | C31: Проектные и изыскательские работы / экспертиза / авторский надзор | D31: =SUM(H9:H30) -> 8.4509878e+08 | E31: руб | F31: 0.012 | G31: =1 -> 1 | H31: =D31*F31 -> 10141185
A32: 2 | B32: 2.8 | C32: Резерв на непредвиденные расходы | D32: =SUM(H9:H31) -> 8.5523996e+08 | E32: руб | F32: =Вводные!$B61 -> 0.05 | G32: =1 -> 1 | H32: =D32*F32 -> 42761998
A33: 2 | B33: 2.9 | C33: Резерв на инфляционное удорожание | D33: =SUM(H9:H32) -> 8.9800196e+08 | E33: руб | F33: =Вводные!$B16*(Вводные!$B8/12) -> 0.114 | G33: =1 -> 1 | H33: =D33*F33 -> 1.0237222e+08
C34: ИТОГО ГЛАВА 2 | H34: =SUM(H9:H33) -> 1.0003742e+09
A35: 3 | B35: 3.1 | C35: Коммерческие расходы | D35: =Продажи!N41 -> 1.4741871e+09 | E35: руб | F35: =Вводные!$B64 -> 0.03 | G35: =1 -> 1 | H35: =D35*F35 -> 44225613
C36: ИТОГО ГЛАВА 3 | H36: =H35 -> 44225613
C37: ИТОГО СТОИМОСТЬ ПРОЕКТА | H37: =H8+H34+H36 -> 1.0445998e+09
C39: ИТОГО СМР (2.1–2.5) | H39: =SUM(H9:H29) -> 8.2448661e+08 | K39: =SUM(K9:K29) -> 5.2857332e+08 | L39: =SUM(L9:L29) -> 2.9591329e+08
C40: ИТОГО материалы СМР | K40: =SUM(K9:K29) -> 5.2857332e+08
C41: ИТОГО работы СМР | L41: =SUM(L9:L29) -> 2.9591329e+08

Sheet ГПР
A1: ГРАФИК ПРОИЗВОДСТВА РАБОТ
A2: Сроки этапов привязаны к Вводные!B8 (Срок строительства)
A3: Этап | B3: Начало, мес | C3: Длительность, мес | D3: Окончание, мес | E3: Стоимость | F3: 1 | G3: 2 | H3: 3 | I3: 4 | J3: 5 | K3: 6 | L3: 7 | M3: 8 | N3: 9 | O3: 10 | P3: 11 | Q3: 12 | R3: 13 | S3: 14 | T3: 15 | U3: 16 | V3: 17 | W3: 18 | X3: 19 | Y3: 20 | Z3: 21 | AA3: 22 | AB3: 23 | AC3: 24 | AD3: 25 | AE3: 26 | AF3: 27 | AG3: 28 | AH3: 29 | AI3: 30 | AJ3: 31 | AK3: 32 | AL3: 33 | AM3: 34 | AN3: 35 | AO3: 36
A4: Подготовительный период | B4: =1 -> 1 | C4: =MAX(1,ROUNDUP(Вводные!$B$8*0.1,0)) -> 2 | D4: =B4+C4-1 -> 2 | E4: =Структура_затрат!H9 -> 14148576 | F4: =IF(AND(F$3>=$B4,F$3<=$D4),$E4/$C4,0) -> 7074288 | G4: =IF(AND(G$3>=$B4,G$3<=$D4),$E4/$C4,0) -> 7074288 | H4: =IF(AND(H$3>=$B4,H$3<=$D4),$E4/$C4,0) -> 0 | I4: =IF(AND(I$3>=$B4,I$3<=$D4),$E4/$C4,0) -> 0 | J4: =IF(AND(J$3>=$B4,J$3<=$D4),$E4/$C4,0) -> 0 | K4: =IF(AND(K$3>=$B4,K$3<=$D4),$E4/$C4,0) -> 0 | L4: =IF(AND(L$3>=$B4,L$3<=$D4),$E4/$C4,0) -> 0 | M4: =IF(AND(M$3>=$B4,M$3<=$D4),$E4/$C4,0) -> 0 | ... AO4: =IF(AND(AO$3>=$B4,AO$3<=$D4),$E4/$C4,0) -> 0
A5: Земляные работы | B5: =MAX(1,ROUNDUP(Вводные!$B$8*0.08,0)) -> 2 | C5: =MAX(1,ROUNDUP(Вводные!$B$8*0.1,0)) -> 2 | D5: =B5+C5-1 -> 3 | E5: =Структура_затрат!H10 -> 19431540 | F5: =IF(AND(F$3>=$B5,F$3<=$D5),$E5/$C5,0) -> 0 | G5: =IF(AND(G$3>=$B5,G$3<=$D5),$E5/$C5,0) -> 9715770 | H5: =IF(AND(H$3>=$B5,H$3<=$D5),$E5/$C5,0) -> 9715770 | I5: =IF(AND(I$3>=$B5,I$3<=$D5),$E5/$C5,0) -> 0 | J5: =IF(AND(J$3>=$B5,J$3<=$D5),$E5/$C5,0) -> 0 | K5: =IF(AND(K$3>=$B5,K$3<=$D5),$E5/$C5,0) -> 0 | L5: =IF(AND(L$3>=$B5,L$3<=$D5),$E5/$C5,0) -> 0 | M5: =IF(AND(M$3>=$B5,M$3<=$D5),$E5/$C5,0) -> 0 | ... AO5: =IF(AND(AO$3>=$B5,AO$3<=$D5),$E5/$C5,0) -> 0
A6: Фундамент / сваи / котлован | B6: =MAX(1,ROUNDUP(Вводные!$B$8*0.12,0)) -> 3 | C6: =MAX(1,ROUNDUP(Вводные!$B$8*0.15,0)) -> 3 | D6: =B6+C6-1 -> 5 | E6: =Структура_затрат!H11 -> 82584045 | F6: =IF(AND(F$3>=$B6,F$3<=$D6),$E6/$C6,0) -> 0 | G6: =IF(AND(G$3>=$B6,G$3<=$D6),$E6/$C6,0) -> 0 | H6: =IF(AND(H$3>=$B6,H$3<=$D6),$E6/$C6,0) -> 27528015 | I6: =IF(AND(I$3>=$B6,I$3<=$D6),$E6/$C6,0) -> 27528015 | J6: =IF(AND(J$3>=$B6,J$3<=$D6),$E6/$C6,0) -> 27528015 | K6: =IF(AND(K$3>=$B6,K$3<=$D6),$E6/$C6,0) -> 0 | L6: =IF(AND(L$3>=$B6,L$3<=$D6),$E6/$C6,0) -> 0 | M6: =IF(AND(M$3>=$B6,M$3<=$D6),$E6/$C6,0) -> 0 | ... AO6: =IF(AND(AO$3>=$B6,AO$3<=$D6),$E6/$C6,0) -> 0
A7: Подземная часть | B7: =MAX(1,ROUNDUP(Вводные!$B$8*0.18,0)) -> 4 | C7: =MAX(1,ROUNDUP(Вводные!$B$8*0.15,0)) -> 3 | D7: =B7+C7-1 -> 6 | E7: =Структура_затрат!H12 -> 0 | F7: =IF(AND(F$3>=$B7,F$3<=$D7),$E7/$C7,0) -> 0 | G7: =IF(AND(G$3>=$B7,G$3<=$D7),$E7/$C7,0) -> 0 | H7: =IF(AND(H$3>=$B7,H$3<=$D7),$E7/$C7,0) -> 0 | I7: =IF(AND(I$3>=$B7,I$3<=$D7),$E7/$C7,0) -> 0 | J7: =IF(AND(J$3>=$B7,J$3<=$D7),$E7/$C7,0) -> 0 | K7: =IF(AND(K$3>=$B7,K$3<=$D7),$E7/$C7,0) -> 0 | L7: =IF(AND(L$3>=$B7,L$3<=$D7),$E7/$C7,0) -> 0 | M7: =IF(AND(M$3>=$B7,M$3<=$D7),$E7/$C7,0) -> 0 | ... AO7: =IF(AND(AO$3>=$B7,AO$3<=$D7),$E7/$C7,0) -> 0
A8: Надземная часть | B8: =MAX(1,ROUNDUP(Вводные!$B$8*0.25,0)) -> 5 | C8: =MAX(1,ROUNDUP(Вводные!$B$8*0.45,0)) -> 9 | D8: =B8+C8-1 -> 13 | E8: =Структура_затрат!H13 -> 214826470 | F8: =IF(AND(F$3>=$B8,F$3<=$D8),$E8/$C8,0) -> 0 | G8: =IF(AND(G$3>=$B8,G$3<=$D8),$E8/$C8,0) -> 0 | H8: =IF(AND(H$3>=$B8,H$3<=$D8),$E8/$C8,0) -> 0 | I8: =IF(AND(I$3>=$B8,I$3<=$D8),$E8/$C8,0) -> 0 | J8: =IF(AND(J$3>=$B8,J$3<=$D8),$E8/$C8,0) -> 23869608 | K8: =IF(AND(K$3>=$B8,K$3<=$D8),$E8/$C8,0) -> 23869608 | L8: =IF(AND(L$3>=$B8,L$3<=$D8),$E8/$C8,0) -> 23869608 | M8: =IF(AND(M$3>=$B8,M$3<=$D8),$E8/$C8,0) -> 23869608 | ... AO8: =IF(AND(AO$3>=$B8,AO$3<=$D8),$E8/$C8,0) -> 0
A9: Фасады / кровля / проемы | B9: =MAX(1,ROUNDUP(Вводные!$B$8*0.45,0)) -> 9 | C9: =MAX(1,ROUNDUP(Вводные!$B$8*0.33,0)) -> 6 | D9: =B9+C9-1 -> 14 | E9: =Структура_затрат!H14+Структура_затрат!H17 -> 197553990 | F9: =IF(AND(F$3>=$B9,F$3<=$D9),$E9/$C9,0) -> 0 | G9: =IF(AND(G$3>=$B9,G$3<=$D9),$E9/$C9,0) -> 0 | H9: =IF(AND(H$3>=$B9,H$3<=$D9),$E9/$C9,0) -> 0 | I9: =IF(AND(I$3>=$B9,I$3<=$D9),$E9/$C9,0) -> 0 | J9: =IF(AND(J$3>=$B9,J$3<=$D9),$E9/$C9,0) -> 0 | K9: =IF(AND(K$3>=$B9,K$3<=$D9),$E9/$C9,0) -> 0 | L9: =IF(AND(L$3>=$B9,L$3<=$D9),$E9/$C9,0) -> 0 | M9: =IF(AND(M$3>=$B9,M$3<=$D9),$E9/$C9,0) -> 0 | ... AO9: =IF(AND(AO$3>=$B9,AO$3<=$D9),$E9/$C9,0) -> 0
A10: Инженерные системы | B10: =MAX(1,ROUNDUP(Вводные!$B$8*0.48,0)) -> 9 | C10: =MAX(1,ROUNDUP(Вводные!$B$8*0.37,0)) -> 7 | D10: =B10+C10-1 -> 15 | E10: =SUM(Структура_затрат!H18:H22) -> 171429364 | F10: =IF(AND(F$3>=$B10,F$3<=$D10),$E10/$C10,0) -> 0 | G10: =IF(AND(G$3>=$B10,G$3<=$D10),$E10/$C10,0) -> 0 | H10: =IF(AND(H$3>=$B10,H$3<=$D10),$E10/$C10,0) -> 0 | I10: =IF(AND(I$3>=$B10,I$3<=$D10),$E10/$C10,0) -> 0 | J10: =IF(AND(J$3>=$B10,J$3<=$D10),$E10/$C10,0) -> 0 | K10: =IF(AND(K$3>=$B10,K$3<=$D10),$E10/$C10,0) -> 0 | L10: =IF(AND(L$3>=$B10,L$3<=$D10),$E10/$C10,0) -> 0 | M10: =IF(AND(M$3>=$B10,M$3<=$D10),$E10/$C10,0) -> 0 | ... AO10: =IF(AND(AO$3>=$B10,AO$3<=$D10),$E10/$C10,0) -> 0
A11: Отделка МОП / техпомещений / реализуемых площадей | B11: =MAX(1,ROUNDUP(Вводные!$B$8*0.56,0)) -> 11 | C11: =MAX(1,ROUNDUP(Вводные!$B$8*0.33,0)) -> 6 | D11: =B11+C11-1 -> 16 | E11: =Структура_затрат!H15+Структура_затрат!H16 -> 65311565 | F11: =IF(AND(F$3>=$B11,F$3<=$D11),$E11/$C11,0) -> 0 | G11: =IF(AND(G$3>=$B11,G$3<=$D11),$E11/$C11,0) -> 0 | H11: =IF(AND(H$3>=$B11,H$3<=$D11),$E11/$C11,0) -> 0 | I11: =IF(AND(I$3>=$B11,I$3<=$D11),$E11/$C11,0) -> 0 | J11: =IF(AND(J$3>=$B11,J$3<=$D11),$E11/$C11,0) -> 0 | K11: =IF(AND(K$3>=$B11,K$3<=$D11),$E11/$C11,0) -> 0 | L11: =IF(AND(L$3>=$B11,L$3<=$D11),$E11/$C11,0) -> 0 | M11: =IF(AND(M$3>=$B11,M$3<=$D11),$E11/$C11,0) -> 0 | ... AO11: =IF(AND(AO$3>=$B11,AO$3<=$D11),$E11/$C11,0) -> 0
A12: Наружные сети | B12: =MAX(1,ROUNDUP(Вводные!$B$8*0.52,0)) -> 10 | C12: =MAX(1,ROUNDUP(Вводные!$B$8*0.3,0)) -> 6 | D12: =B12+C12-1 -> 15 | E12: =SUM(Структура_затрат!H24:H28) -> 28218549 | F12: =IF(AND(F$3>=$B12,F$3<=$D12),$E12/$C12,0) -> 0 | G12: =IF(AND(G$3>=$B12,G$3<=$D12),$E12/$C12,0) -> 0 | H12: =IF(AND(H$3>=$B12,H$3<=$D12),$E12/$C12,0) -> 0 | I12: =IF(AND(I$3>=$B12,I$3<=$D12),$E12/$C12,0) -> 0 | J12: =IF(AND(J$3>=$B12,J$3<=$D12),$E12/$C12,0) -> 0 | K12: =IF(AND(K$3>=$B12,K$3<=$D12),$E12/$C12,0) -> 0 | L12: =IF(AND(L$3>=$B12,L$3<=$D12),$E12/$C12,0) -> 0 | M12: =IF(AND(M$3>=$B12,M$3<=$D12),$E12/$C12,0) -> 0 | ... AO12: =IF(AND(AO$3>=$B12,AO$3<=$D12),$E12/$C12,0) -> 0
A13: Благоустройство и озеленение | B13: =MAX(1,ROUNDUP(Вводные!$B$8*0.82,0)) -> 15 | C13: =MAX(1,ROUNDUP(Вводные!$B$8*0.15,0)) -> 3 | D13: =B13+C13-1 -> 17 | E13: =Структура_затрат!H29 -> 30982511 | F13: =IF(AND(F$3>=$B13,F$3<=$D13),$E13/$C13,0) -> 0 | G13: =IF(AND(G$3>=$B13,G$3<=$D13),$E13/$C13,0) -> 0 | H13: =IF(AND(H$3>=$B13,H$3<=$D13),$E13/$C13,0) -> 0 | I13: =IF(AND(I$3>=$B13,I$3<=$D13),$E13/$C13,0) -> 0 | J13: =IF(AND(J$3>=$B13,J$3<=$D13),$E13/$C13,0) -> 0 | K13: =IF(AND(K$3>=$B13,K$3<=$D13),$E13/$C13,0) -> 0 | L13: =IF(AND(L$3>=$B13,L$3<=$D13),$E13/$C13,0) -> 0 | M13: =IF(AND(M$3>=$B13,M$3<=$D13),$E13/$C13,0) -> 0 | ... AO13: =IF(AND(AO$3>=$B13,AO$3<=$D13),$E13/$C13,0) -> 0
A14: Заказчик / проектирование / резервы | B14: =1 -> 1 | C14: =MAX(1,Вводные!$B$8) -> 18 | D14: =B14+C14-1 -> 18 | E14: =SUM(Структура_затрат!H30:H33) -> 1.7588757e+08 | F14: =SUM(F4:F13) -> 7074288 | G14: =SUM(G4:G13) -> 16790058 | H14: =SUM(H4:H13) -> 37243785 | I14: =SUM(I4:I13) -> 27528015 | J14: =SUM(J4:J13) -> 51397623 | K14: =SUM(K4:K13) -> 23869608 | L14: =SUM(L4:L13) -> 23869608 | M14: =SUM(M4:M13) -> 23869608 | ... AO14: =SUM(AO4:AO13) -> 0
A16: ИТОГО CAPEX В МЕСЯЦ | F16: =SUM(F4:F14) -> 14148576 | G16: =SUM(G4:G14) -> 33580116 | H16: =SUM(H4:H14) -> 74487570 | I16: =SUM(I4:I14) -> 55056030 | J16: =SUM(J4:J14) -> 1.0279525e+08 | K16: =SUM(K4:K14) -> 47739216 | L16: =SUM(L4:L14) -> 47739216 | M16: =SUM(M4:M14) -> 47739216 | ... AO16: =SUM(AO4:AO14) -> 0

Sheet Продажи
A1: ПРОДАЖИ И ВЫРУЧКА
A3: Месяц | B3: Дата | C3: Вес продаж | D3: Доля | E3: Продано, м2 | F3: Цена, руб/м2 | G3: Выручка квартир | H3: Продано м/мест | I3: Выручка м/мест | J3: Итого выручка | K3: Накопленная выручка | L3: Эскроу накопленно | M3: Раскрытие эскроу | N3: Итого выручка проекта | O3: Средняя цена | P3: Доступно на обслуживание долга
A4: 1 | B4: 46054 | C4: 1 | D4: =IF($A4<=Вводные!$B9,C4/SUMPRODUCT(($A$4:$A$39<=Вводные!$B9)*$C$4:$C$39),0) -> 0.019230769 | E4: =IF($A4<=Вводные!$B9,Вводные!$B11*D4,0) -> 151.16 | F4: =Вводные!$B13*(1+Вводные!$B15)^((A4-1)/12) -> 175000 | G4: =E4*F4 -> 26453000 | H4: =IF(AND($A4>=MAX(1,Вводные!$B9-MIN(6,Вводные!$B9)+1),$A4<=Вводные!$B9),Вводные!$B12/MIN(6,Вводные!$B9),0) -> 0 | I4: =H4*Вводные!$B14 -> 0 | J4: =G4+I4 -> 26453000 | K4: =SUM($J$4:J4) -> 26453000 | L4: =K4 -> 26453000 | M4: =IF(AND(YEAR(B4)=YEAR(Вводные!$B$28),MONTH(B4)=MONTH(Вводные!$B$28)),L4,0) -> 0 | N4: =J4 -> 26453000 | O4: =IF(E4=0,0,G4/E4) -> 175000 | P4: =IF(B4<Вводные!$B$28,0,IF(AND(YEAR(B4)=YEAR(Вводные!$B$28),MONTH(B4)=MONTH(Вводные!$B$28)),M4,J4)) -> 0
A5: 2 | B5: 46082 | C5: 1 | D5: =IF($A5<=Вводные!$B9,C5/SUMPRODUCT(($A$4:$A$39<=Вводные!$B9)*$C$4:$C$39),0) -> 0.019230769 | E5: =IF($A5<=Вводные!$B9,Вводные!$B11*D5,0) -> 151.16 | F5: =Вводные!$B13*(1+Вводные!$B15)^((A5-1)/12) -> 176125.96 | G5: =E5*F5 -> 26623199 | H5: =IF(AND($A5>=MAX(1,Вводные!$B9-MIN(6,Вводные!$B9)+1),$A5<=Вводные!$B9),Вводные!$B12/MIN(6,Вводные!$B9),0) -> 0 | I5: =H5*Вводные!$B14 -> 0 | J5: =G5+I5 -> 26623199 | K5: =SUM($J$4:J5) -> 53076199 | L5: =K5 -> 53076199 | M5: =IF(AND(YEAR(B5)=YEAR(Вводные!$B$28),MONTH(B5)=MONTH(Вводные!$B$28)),L5,0) -> 0 | N5: =J5 -> 26623199 | O5: =IF(E5=0,0,G5/E5) -> 176125.96 | P5: =IF(B5<Вводные!$B$28,0,IF(AND(YEAR(B5)=YEAR(Вводные!$B$28),MONTH(B5)=MONTH(Вводные!$B$28)),M5,J5)) -> 0
A6: 3 | B6: 46113 | C6: 1 | D6: =IF($A6<=Вводные!$B9,C6/SUMPRODUCT(($A$4:$A$39<=Вводные!$B9)*$C$4:$C$39),0) -> 0.019230769 | E6: =IF($A6<=Вводные!$B9,Вводные!$B11*D6,0) -> 151.16 | F6: =Вводные!$B13*(1+Вводные!$B15)^((A6-1)/12) -> 177259.15 | G6: =E6*F6 -> 26794494 | H6: =IF(AND($A6>=MAX(1,Вводные!$B9-MIN(6,Вводные!$B9)+1),$A6<=Вводные!$B9),Вводные!$B12/MIN(6,Вводные!$B9),0) -> 0 | I6: =H6*Вводные!$B14 -> 0 | J6: =G6+I6 -> 26794494 | K6: =SUM($J$4:J6) -> 79870693 | L6: =K6 -> 79870693 | M6: =IF(AND(YEAR(B6)=YEAR(Вводные!$B$28),MONTH(B6)=MONTH(Вводные!$B$28)),L6,0) -> 0 | N6: =J6 -> 26794494 | O6: =IF(E6=0,0,G6/E6) -> 177259.15 | P6: =IF(B6<Вводные!$B$28,0,IF(AND(YEAR(B6)=YEAR(Вводные!$B$28),MONTH(B6)=MONTH(Вводные!$B$28)),M6,J6)) -> 0
A7: 4 | B7: 46143 | C7: 1 | D7: =IF($A7<=Вводные!$B9,C7/SUMPRODUCT(($A$4:$A$39<=Вводные!$B9)*$C$4:$C$39),0) -> 0.019230769 | E7: =IF($A7<=Вводные!$B9,Вводные!$B11*D7,0) -> 151.16 | F7: =Вводные!$B13*(1+Вводные!$B15)^((A7-1)/12) -> 178399.65 | G7: =E7*F7 -> 26966890 | H7: =IF(AND($A7>=MAX(1,Вводные!$B9-MIN(6,Вводные!$B9)+1),$A7<=Вводные!$B9),Вводные!$B12/MIN(6,Вводные!$B9),0) -> 0 | I7: =H7*Вводные!$B14 -> 0 | J7: =G7+I7 -> 26966890 | K7: =SUM($J$4:J7) -> 1.0683758e+08 | L7: =K7 -> 1.0683758e+08 | M7: =IF(AND(YEAR(B7)=YEAR(Вводные!$B$28),MONTH(B7)=MONTH(Вводные!$B$28)),L7,0) -> 0 | N7: =J7 -> 26966890 | O7: =IF(E7=0,0,G7/E7) -> 178399.65 | P7: =IF(B7<Вводные!$B$28,0,IF(AND(YEAR(B7)=YEAR(Вводные!$B$28),MONTH(B7)=MONTH(Вводные!$B$28)),M7,J7)) -> 0
A8: 5 | B8: 46174 | C8: 2 | D8: =IF($A8<=Вводные!$B9,C8/SUMPRODUCT(($A$4:$A$39<=Вводные!$B9)*$C$4:$C$39),0) -> 0.038461538 | E8: =IF($A8<=Вводные!$B9,Вводные!$B11*D8,0) -> 302.32 | F8: =Вводные!$B13*(1+Вводные!$B15)^((A8-1)/12) -> 179547.47 | G8: =E8*F8 -> 54280792 | H8: =IF(AND($A8>=MAX(1,Вводные!$B9-MIN(6,Вводные!$B9)+1),$A8<=Вводные!$B9),Вводные!$B12/MIN(6,Вводные!$B9),0) -> 0 | I8: =H8*Вводные!$B14 -> 0 | J8: =G8+I8 -> 54280792 | K8: =SUM($J$4:J8) -> 1.6111838e+08 | L8: =K8 -> 1.6111838e+08 | M8: =IF(AND(YEAR(B8)=YEAR(Вводные!$B$28),MONTH(B8)=MONTH(Вводные!$B$28)),L8,0) -> 0 | N8: =J8 -> 54280792 | O8: =IF(E8=0,0,G8/E8) -> 179547.47 | P8: =IF(B8<Вводные!$B$28,0,IF(AND(YEAR(B8)=YEAR(Вводные!$B$28),MONTH(B8)=MONTH(Вводные!$B$28)),M8,J8)) -> 0
A9: 6 | B9: 46204 | C9: 2 | D9: =IF($A9<=Вводные!$B9,C9/SUMPRODUCT(($A$4:$A$39<=Вводные!$B9)*$C$4:$C$39),0) -> 0.038461538 | E9: =IF($A9<=Вводные!$B9,Вводные!$B11*D9,0) -> 302.32 | F9: =Вводные!$B13*(1+Вводные!$B15)^((A9-1)/12) -> 180702.69 | G9: =E9*F9 -> 54630037 | H9: =IF(AND($A9>=MAX(1,Вводные!$B9-MIN(6,Вводные!$B9)+1),$A9<=Вводные!$B9),Вводные!$B12/MIN(6,Вводные!$B9),0) -> 0 | I9: =H9*Вводные!$B14 -> 0 | J9: =G9+I9 -> 54630037 | K9: =SUM($J$4:J9) -> 2.1574841e+08 | L9: =K9 -> 2.1574841e+08 | M9: =IF(AND(YEAR(B9)=YEAR(Вводные!$B$28),MONTH(B9)=MONTH(Вводные!$B$28)),L9,0) -> 0 | N9: =J9 -> 54630037 | O9: =IF(E9=0,0,G9/E9) -> 180702.69 | P9: =IF(B9<Вводные!$B$28,0,IF(AND(YEAR(B9)=YEAR(Вводные!$B$28),MONTH(B9)=MONTH(Вводные!$B$28)),M9,J9)) -> 0
A10: 7 | B10: 46235 | C10: 3 | D10: =IF($A10<=Вводные!$B9,C10/SUMPRODUCT(($A$4:$A$39<=Вводные!$B9)*$C$4:$C$39),0) -> 0.057692308 | E10: =IF($A10<=Вводные!$B9,Вводные!$B11*D10,0) -> 453.48 | F10: =Вводные!$B13*(1+Вводные!$B15)^((A10-1)/12) -> 181865.33 | G10: =E10*F10 -> 82472292 | H10: =IF(AND($A10>=MAX(1,Вводные!$B9-MIN(6,Вводные!$B9)+1),$A10<=Вводные!$B9),Вводные!$B12/MIN(6,Вводные!$B9),0) -> 0 | I10: =H10*Вводные!$B14 -> 0 | J10: =G10+I10 -> 82472292 | K10: =SUM($J$4:J10) -> 2.982207e+08 | L10: =K10 -> 2.982207e+08 | M10: =IF(AND(YEAR(B10)=YEAR(Вводные!$B$28),MONTH(B10)=MONTH(Вводные!$B$28)),L10,0) -> 0 | N10: =J10 -> 82472292 | O10: =IF(E10=0,0,G10/E10) -> 181865.33 | P10: =IF(B10<Вводные!$B$28,0,IF(AND(YEAR(B10)=YEAR(Вводные!$B$28),MONTH(B10)=MONTH(Вводные!$B$28)),M10,J10)) -> 0
A11: 8 | B11: 46266 | C11: 3 | D11: =IF($A11<=Вводные!$B9,C11/SUMPRODUCT(($A$4:$A$39<=Вводные!$B9)*$C$4:$C$39),0) -> 0.057692308 | E11: =IF($A11<=Вводные!$B9,Вводные!$B11*D11,0) -> 453.48 | F11: =Вводные!$B13*(1+Вводные!$B15)^((A11-1)/12) -> 183035.46 | G11: =E11*F11 -> 83002921 | H11: =IF(AND($A11>=MAX(1,Вводные!$B9-MIN(6,Вводные!$B9)+1),$A11<=Вводные!$B9),Вводные!$B12/MIN(6,Вводные!$B9),0) -> 0 | I11: =H11*Вводные!$B14 -> 0 | J11: =G11+I11 -> 83002921 | K11: =SUM($J$4:J11) -> 3.8122363e+08 | L11: =K11 -> 3.8122363e+08 | M11: =IF(AND(YEAR(B11)=YEAR(Вводные!$B$28),MONTH(B11)=MONTH(Вводные!$B$28)),L11,0) -> 0 | N11: =J11 -> 83002921 | O11: =IF(E11=0,0,G11/E11) -> 183035.46 | P11: =IF(B11<Вводные!$B$28,0,IF(AND(YEAR(B11)=YEAR(Вводные!$B$28),MONTH(B11)=MONTH(Вводные!$B$28)),M11,J11)) -> 0
A12: 9 | B12: 46296 | C12: 4 | D12: =IF($A12<=Вводные!$B9,C12/SUMPRODUCT(($A$4:$A$39<=Вводные!$B9)*$C$4:$C$39),0) -> 0.076923077 | E12: =IF($A12<=Вводные!$B9,Вводные!$B11*D12,0) -> 604.64 | F12: =Вводные!$B13*(1+Вводные!$B15)^((A12-1)/12) -> 184213.12 | G12: =E12*F12 -> 1.1138262e+08 | H12: =IF(AND($A12>=MAX(1,Вводные!$B9-MIN(6,Вводные!$B9)+1),$A12<=Вводные!$B9),Вводные!$B12/MIN(6,Вводные!$B9),0) -> 0 | I12: =H12*Вводные!$B14 -> 0 | J12: =G12+I12 -> 1.1138262e+08 | K12: =SUM($J$4:J12) -> 4.9260625e+08 | L12: =K12 -> 4.9260625e+08 | M12: =IF(AND(YEAR(B12)=YEAR(Вводные!$B$28),MONTH(B12)=MONTH(Вводные!$B$28)),L12,0) -> 0 | N12: =J12 -> 1.1138262e+08 | O12: =IF(E12=0,0,G12/E12) -> 184213.12 | P12: =IF(B12<Вводные!$B$28,0,IF(AND(YEAR(B12)=YEAR(Вводные!$B$28),MONTH(B12)=MONTH(Вводные!$B$28)),M12,J12)) -> 0
A13: 10 | B13: 46327 | C13: 4 | D13: =IF($A13<=Вводные!$B9,C13/SUMPRODUCT(($A$4:$A$39<=Вводные!$B9)*$C$4:$C$39),0) -> 0.076923077 | E13: =IF($A13<=Вводные!$B9,Вводные!$B11*D13,0) -> 604.64 | F13: =Вводные!$B13*(1+Вводные!$B15)^((A13-1)/12) -> 185398.35 | G13: =E13*F13 -> 1.1209926e+08 | H13: =IF(AND($A13>=MAX(1,Вводные!$B9-MIN(6,Вводные!$B9)+1),$A13<=Вводные!$B9),Вводные!$B12/MIN(6,Вводные!$B9),0) -> 0 | I13: =H13*Вводные!$B14 -> 0 | J13: =G13+I13 -> 1.1209926e+08 | K13: =SUM($J$4:J13) -> 6.047055e+08 | L13: =K13 -> 6.047055e+08 | M13: =IF(AND(YEAR(B13)=YEAR(Вводные!$B$28),MONTH(B13)=MONTH(Вводные!$B$28)),L13,0) -> 0 | N13: =J13 -> 1.1209926e+08 | O13: =IF(E13=0,0,G13/E13) -> 185398.35 | P13: =IF(B13<Вводные!$B$28,0,IF(AND(YEAR(B13)=YEAR(Вводные!$B$28),MONTH(B13)=MONTH(Вводные!$B$28)),M13,J13)) -> 0
A14: 11 | B14: 46357 | C14: 5 | D14: =IF($A14<=Вводные!$B9,C14/SUMPRODUCT(($A$4:$A$39<=Вводные!$B9)*$C$4:$C$39),0) -> 0.096153846 | E14: =IF($A14<=Вводные!$B9,Вводные!$B11*D14,0) -> 755.8 | F14: =Вводные!$B13*(1+Вводные!$B15)^((A14-1)/12) -> 186591.21 | G14: =E14*F14 -> 1.4102564e+08 | H14: =IF(AND($A14>=MAX(1,Вводные!$B9-MIN(6,Вводные!$B9)+1),$A14<=Вводные!$B9),Вводные!$B12/MIN(6,Вводные!$B9),0) -> 1 | I14: =H14*Вводные!$B14 -> 1600000 | J14: =G14+I14 -> 1.4262564e+08 | K14: =SUM($J$4:J14) -> 7.4733114e+08 | L14: =K14 -> 7.4733114e+08 | M14: =IF(AND(YEAR(B14)=YEAR(Вводные!$B$28),MONTH(B14)=MONTH(Вводные!$B$28)),L14,0) -> 0 | N14: =J14 -> 1.4262564e+08 | O14: =IF(E14=0,0,G14/E14) -> 186591.21 | P14: =IF(B14<Вводные!$B$28,0,IF(AND(YEAR(B14)=YEAR(Вводные!$B$28),MONTH(B14)=MONTH(Вводные!$B$28)),M14,J14)) -> 0
A15: 12 | B15: 46388 | C15: 5 | D15: =IF($A15<=Вводные!$B9,C15/SUMPRODUCT(($A$4:$A$39<=Вводные!$B9)*$C$4:$C$39),0) -> 0.096153846 | E15: =IF($A15<=Вводные!$B9,Вводные!$B11*D15,0) -> 755.8 | F15: =Вводные!$B13*(1+Вводные!$B15)^((A15-1)/12) -> 187791.74 | G15: =E15*F15 -> 1.41933e+08 | H15: =IF(AND($A15>=MAX(1,Вводные!$B9-MIN(6,Вводные!$B9)+1),$A15<=Вводные!$B9),Вводные!$B12/MIN(6,Вводные!$B9),0) -> 1 | I15: =H15*Вводные!$B14 -> 1600000 | J15: =G15+I15 -> 1.43533e+08 | K15: =SUM($J$4:J15) -> 8.9086414e+08 | L15: =K15 -> 8.9086414e+08 | M15: =IF(AND(YEAR(B15)=YEAR(Вводные!$B$28),MONTH(B15)=MONTH(Вводные!$B$28)),L15,0) -> 0 | N15: =J15 -> 1.43533e+08 | O15: =IF(E15=0,0,G15/E15) -> 187791.74 | P15: =IF(B15<Вводные!$B$28,0,IF(AND(YEAR(B15)=YEAR(Вводные!$B$28),MONTH(B15)=MONTH(Вводные!$B$28)),M15,J15)) -> 0
A16: 13 | B16: 46419 | C16: 5 | D16: =IF($A16<=Вводные!$B9,C16/SUMPRODUCT(($A$4:$A$39<=Вводные!$B9)*$C$4:$C$39),0) -> 0.096153846 | E16: =IF($A16<=Вводные!$B9,Вводные!$B11*D16,0) -> 755.8 | F16: =Вводные!$B13*(1+Вводные!$B15)^((A16-1)/12) -> 189000 | G16: =E16*F16 -> 142846200 | H16: =IF(AND($A16>=MAX(1,Вводные!$B9-MIN(6,Вводные!$B9)+1),$A16<=Вводные!$B9),Вводные!$B12/MIN(6,Вводные!$B9),0) -> 1 | I16: =H16*Вводные!$B14 -> 1600000 | J16: =G16+I16 -> 144446200 | K16: =SUM($J$4:J16) -> 1.0353103e+09 | L16: =K16 -> 1.0353103e+09 | M16: =IF(AND(YEAR(B16)=YEAR(Вводные!$B$28),MONTH(B16)=MONTH(Вводные!$B$28)),L16,0) -> 0 | N16: =J16 -> 144446200 | O16: =IF(E16=0,0,G16/E16) -> 189000 | P16: =IF(B16<Вводные!$B$28,0,IF(AND(YEAR(B16)=YEAR(Вводные!$B$28),MONTH(B16)=MONTH(Вводные!$B$28)),M16,J16)) -> 0
A17: 14 | B17: 46447 | C17: 5 | D17: =IF($A17<=Вводные!$B9,C17/SUMPRODUCT(($A$4:$A$39<=Вводные!$B9)*$C$4:$C$39),0) -> 0.096153846 | E17: =IF($A17<=Вводные!$B9,Вводные!$B11*D17,0) -> 755.8 | F17: =Вводные!$B13*(1+Вводные!$B15)^((A17-1)/12) -> 190216.03 | G17: =E17*F17 -> 1.4376528e+08 | H17: =IF(AND($A17>=MAX(1,Вводные!$B9-MIN(6,Вводные!$B9)+1),$A17<=Вводные!$B9),Вводные!$B12/MIN(6,Вводные!$B9),0) -> 1 | I17: =H17*Вводные!$B14 -> 1600000 | J17: =G17+I17 -> 1.4536528e+08 | K17: =SUM($J$4:J17) -> 1.1806756e+09 | L17: =K17 -> 1.1806756e+09 | M17: =IF(AND(YEAR(B17)=YEAR(Вводные!$B$28),MONTH(B17)=MONTH(Вводные!$B$28)),L17,0) -> 0 | N17: =J17 -> 1.4536528e+08 | O17: =IF(E17=0,0,G17/E17) -> 190216.03 | P17: =IF(B17<Вводные!$B$28,0,IF(AND(YEAR(B17)=YEAR(Вводные!$B$28),MONTH(B17)=MONTH(Вводные!$B$28)),M17,J17)) -> 0
A18: 15 | B18: 46478 | C18: 5 | D18: =IF($A18<=Вводные!$B9,C18/SUMPRODUCT(($A$4:$A$39<=Вводные!$B9)*$C$4:$C$39),0) -> 0.096153846 | E18: =IF($A18<=Вводные!$B9,Вводные!$B11*D18,0) -> 755.8 | F18: =Вводные!$B13*(1+Вводные!$B15)^((A18-1)/12) -> 191439.89 | G18: =E18*F18 -> 1.4469027e+08 | H18: =IF(AND($A18>=MAX(1,Вводные!$B9-MIN(6,Вводные!$B9)+1),$A18<=Вводные!$B9),Вводные!$B12/MIN(6,Вводные!$B9),0) -> 1 | I18: =H18*Вводные!$B14 -> 1600000 | J18: =G18+I18 -> 1.4629027e+08 | K18: =SUM($J$4:J18) -> 1.3269659e+09 | L18: =K18 -> 1.3269659e+09 | M18: =IF(AND(YEAR(B18)=YEAR(Вводные!$B$28),MONTH(B18)=MONTH(Вводные!$B$28)),L18,0) -> 0 | N18: =J18 -> 1.4629027e+08 | O18: =IF(E18=0,0,G18/E18) -> 191439.89 | P18: =IF(B18<Вводные!$B$28,0,IF(AND(YEAR(B18)=YEAR(Вводные!$B$28),MONTH(B18)=MONTH(Вводные!$B$28)),M18,J18)) -> 0
A19: 16 | B19: 46508 | C19: 5 | D19: =IF($A19<=Вводные!$B9,C19/SUMPRODUCT(($A$4:$A$39<=Вводные!$B9)*$C$4:$C$39),0) -> 0.096153846 | E19: =IF($A19<=Вводные!$B9,Вводные!$B11*D19,0) -> 755.8 | F19: =Вводные!$B13*(1+Вводные!$B15)^((A19-1)/12) -> 192671.62 | G19: =E19*F19 -> 1.4562121e+08 | H19: =IF(AND($A19>=MAX(1,Вводные!$B9-MIN(6,Вводные!$B9)+1),$A19<=Вводные!$B9),Вводные!$B12/MIN(6,Вводные!$B9),0) -> 1 | I19: =H19*Вводные!$B14 -> 1600000 | J19: =G19+I19 -> 1.4722121e+08 | K19: =SUM($J$4:J19) -> 1.4741871e+09 | L19: =K19 -> 1.4741871e+09 | M19: =IF(AND(YEAR(B19)=YEAR(Вводные!$B$28),MONTH(B19)=MONTH(Вводные!$B$28)),L19,0) -> 0 | N19: =J19 -> 1.4722121e+08 | O19: =IF(E19=0,0,G19/E19) -> 192671.62 | P19: =IF(B19<Вводные!$B$28,0,IF(AND(YEAR(B19)=YEAR(Вводные!$B$28),MONTH(B19)=MONTH(Вводные!$B$28)),M19,J19)) -> 0
A20: 17 | B20: 46539 | C20: 4 | D20: =IF($A20<=Вводные!$B9,C20/SUMPRODUCT(($A$4:$A$39<=Вводные!$B9)*$C$4:$C$39),0) -> 0 | E20: =IF($A20<=Вводные!$B9,Вводные!$B11*D20,0) -> 0 | F20: =Вводные!$B13*(1+Вводные!$B15)^((A20-1)/12) -> 193911.27 | G20: =E20*F20 -> 0 | H20: =IF(AND($A20>=MAX(1,Вводные!$B9-MIN(6,Вводные!$B9)+1),$A20<=Вводные!$B9),Вводные!$B12/MIN(6,Вводные!$B9),0) -> 0 | I20: =H20*Вводные!$B14 -> 0 | J20: =G20+I20 -> 0 | K20: =SUM($J$4:J20) -> 1.4741871e+09 | L20: =K20 -> 1.4741871e+09 | M20: =IF(AND(YEAR(B20)=YEAR(Вводные!$B$28),MONTH(B20)=MONTH(Вводные!$B$28)),L20,0) -> 0 | N20: =J20 -> 0 | O20: =IF(E20=0,0,G20/E20) -> 0 | P20: =IF(B20<Вводные!$B$28,0,IF(AND(YEAR(B20)=YEAR(Вводные!$B$28),MONTH(B20)=MONTH(Вводные!$B$28)),M20,J20)) -> 0
A21: 18 | B21: 46569 | C21: 4 | D21: =IF($A21<=Вводные!$B9,C21/SUMPRODUCT(($A$4:$A$39<=Вводные!$B9)*$C$4:$C$39),0) -> 0 | E21: =IF($A21<=Вводные!$B9,Вводные!$B11*D21,0) -> 0 | F21: =Вводные!$B13*(1+Вводные!$B15)^((A21-1)/12) -> 195158.9 | G21: =E21*F21 -> 0 | H21: =IF(AND($A21>=MAX(1,Вводные!$B9-MIN(6,Вводные!$B9)+1),$A21<=Вводные!$B9),Вводные!$B12/MIN(6,Вводные!$B9),0) -> 0 | I21: =H21*Вводные!$B14 -> 0 | J21: =G21+I21 -> 0 | K21: =SUM($J$4:J21) -> 1.4741871e+09 | L21: =K21 -> 1.4741871e+09 | M21: =IF(AND(YEAR(B21)=YEAR(Вводные!$B$28),MONTH(B21)=MONTH(Вводные!$B$28)),L21,0) -> 1.4741871e+09 | N21: =J21 -> 0 | O21: =IF(E21=0,0,G21/E21) -> 0 | P21: =IF(B21<Вводные!$B$28,0,IF(AND(YEAR(B21)=YEAR(Вводные!$B$28),MONTH(B21)=MONTH(Вводные!$B$28)),M21,J21)) -> 1.4741871e+09
A22: 19 | B22: 46600 | C22: 4 | D22: =IF($A22<=Вводные!$B9,C22/SUMPRODUCT(($A$4:$A$39<=Вводные!$B9)*$C$4:$C$39),0) -> 0 | E22: =IF($A22<=Вводные!$B9,Вводные!$B11*D22,0) -> 0 | F22: =Вводные!$B13*(1+Вводные!$B15)^((A22-1)/12) -> 196414.56 | G22: =E22*F22 -> 0 | H22: =IF(AND($A22>=MAX(1,Вводные!$B9-MIN(6,Вводные!$B9)+1),$A22<=Вводные!$B9),Вводные!$B12/MIN(6,Вводные!$B9),0) -> 0 | I22: =H22*Вводные!$B14 -> 0 | J22: =G22+I22 -> 0 | K22: =SUM($J$4:J22) -> 1.4741871e+09 | L22: =K22 -> 1.4741871e+09 | M22: =IF(AND(YEAR(B22)=YEAR(Вводные!$B$28),MONTH(B22)=MONTH(Вводные!$B$28)),L22,0) -> 0 | N22: =J22 -> 0 | O22: =IF(E22=0,0,G22/E22) -> 0 | P22: =IF(B22<Вводные!$B$28,0,IF(AND(YEAR(B22)=YEAR(Вводные!$B$28),MONTH(B22)=MONTH(Вводные!$B$28)),M22,J22)) -> 0
A23: 20 | B23: 46631 | C23: 4 | D23: =IF($A23<=Вводные!$B9,C23/SUMPRODUCT(($A$4:$A$39<=Вводные!$B9)*$C$4:$C$39),0) -> 0 | E23: =IF($A23<=Вводные!$B9,Вводные!$B11*D23,0) -> 0 | F23: =Вводные!$B13*(1+Вводные!$B15)^((A23-1)/12) -> 197678.3 | G23: =E23*F23 -> 0 | H23: =IF(AND($A23>=MAX(1,Вводные!$B9-MIN(6,Вводные!$B9)+1),$A23<=Вводные!$B9),Вводные!$B12/MIN(6,Вводные!$B9),0) -> 0 | I23: =H23*Вводные!$B14 -> 0 | J23: =G23+I23 -> 0 | K23: =SUM($J$4:J23) -> 1.4741871e+09 | L23: =K23 -> 1.4741871e+09 | M23: =IF(AND(YEAR(B23)=YEAR(Вводные!$B$28),MONTH(B23)=MONTH(Вводные!$B$28)),L23,0) -> 0 | N23: =J23 -> 0 | O23: =IF(E23=0,0,G23/E23) -> 0 | P23: =IF(B23<Вводные!$B$28,0,IF(AND(YEAR(B23)=YEAR(Вводные!$B$28),MONTH(B23)=MONTH(Вводные!$B$28)),M23,J23)) -> 0
A24: 21 | B24: 46661 | C24: 3 | D24: =IF($A24<=Вводные!$B9,C24/SUMPRODUCT(($A$4:$A$39<=Вводные!$B9)*$C$4:$C$39),0) -> 0 | E24: =IF($A24<=Вводные!$B9,Вводные!$B11*D24,0) -> 0 | F24: =Вводные!$B13*(1+Вводные!$B15)^((A24-1)/12) -> 198950.17 | G24: =E24*F24 -> 0 | H24: =IF(AND($A24>=MAX(1,Вводные!$B9-MIN(6,Вводные!$B9)+1),$A24<=Вводные!$B9),Вводные!$B12/MIN(6,Вводные!$B9),0) -> 0 | I24: =H24*Вводные!$B14 -> 0 | J24: =G24+I24 -> 0 | K24: =SUM($J$4:J24) -> 1.4741871e+09 | L24: =K24 -> 1.4741871e+09 | M24: =IF(AND(YEAR(B24)=YEAR(Вводные!$B$28),MONTH(B24)=MONTH(Вводные!$B$28)),L24,0) -> 0 | N24: =J24 -> 0 | O24: =IF(E24=0,0,G24/E24) -> 0 | P24: =IF(B24<Вводные!$B$28,0,IF(AND(YEAR(B24)=YEAR(Вводные!$B$28),MONTH(B24)=MONTH(Вводные!$B$28)),M24,J24)) -> 0
A25: 22 | B25: 46692 | C25: 3 | D25: =IF($A25<=Вводные!$B9,C25/SUMPRODUCT(($A$4:$A$39<=Вводные!$B9)*$C$4:$C$39),0) -> 0 | E25: =IF($A25<=Вводные!$B9,Вводные!$B11*D25,0) -> 0 | F25: =Вводные!$B13*(1+Вводные!$B15)^((A25-1)/12) -> 200230.22 | G25: =E25*F25 -> 0 | H25: =IF(AND($A25>=MAX(1,Вводные!$B9-MIN(6,Вводные!$B9)+1),$A25<=Вводные!$B9),Вводные!$B12/MIN(6,Вводные!$B9),0) -> 0 | I25: =H25*Вводные!$B14 -> 0 | J25: =G25+I25 -> 0 | K25: =SUM($J$4:J25) -> 1.4741871e+09 | L25: =K25 -> 1.4741871e+09 | M25: =IF(AND(YEAR(B25)=YEAR(Вводные!$B$28),MONTH(B25)=MONTH(Вводные!$B$28)),L25,0) -> 0 | N25: =J25 -> 0 | O25: =IF(E25=0,0,G25/E25) -> 0 | P25: =IF(B25<Вводные!$B$28,0,IF(AND(YEAR(B25)=YEAR(Вводные!$B$28),MONTH(B25)=MONTH(Вводные!$B$28)),M25,J25)) -> 0
A26: 23 | B26: 46722 | C26: 3 | D26: =IF($A26<=Вводные!$B9,C26/SUMPRODUCT(($A$4:$A$39<=Вводные!$B9)*$C$4:$C$39),0) -> 0 | E26: =IF($A26<=Вводные!$B9,Вводные!$B11*D26,0) -> 0 | F26: =Вводные!$B13*(1+Вводные!$B15)^((A26-1)/12) -> 201518.51 | G26: =E26*F26 -> 0 | H26: =IF(AND($A26>=MAX(1,Вводные!$B9-MIN(6,Вводные!$B9)+1),$A26<=Вводные!$B9),Вводные!$B12/MIN(6,Вводные!$B9),0) -> 0 | I26: =H26*Вводные!$B14 -> 0 | J26: =G26+I26 -> 0 | K26: =SUM($J$4:J26) -> 1.4741871e+09 | L26: =K26 -> 1.4741871e+09 | M26: =IF(AND(YEAR(B26)=YEAR(Вводные!$B$28),MONTH(B26)=MONTH(Вводные!$B$28)),L26,0) -> 0 | N26: =J26 -> 0 | O26: =IF(E26=0,0,G26/E26) -> 0 | P26: =IF(B26<Вводные!$B$28,0,IF(AND(YEAR(B26)=YEAR(Вводные!$B$28),MONTH(B26)=MONTH(Вводные!$B$28)),M26,J26)) -> 0
A27: 24 | B27: 46753 | C27: 2 | D27: =IF($A27<=Вводные!$B9,C27/SUMPRODUCT(($A$4:$A$39<=Вводные!$B9)*$C$4:$C$39),0) -> 0 | E27: =IF($A27<=Вводные!$B9,Вводные!$B11*D27,0) -> 0 | F27: =Вводные!$B13*(1+Вводные!$B15)^((A27-1)/12) -> 202815.08 | G27: =E27*F27 -> 0 | H27: =IF(AND($A27>=MAX(1,Вводные!$B9-MIN(6,Вводные!$B9)+1),$A27<=Вводные!$B9),Вводные!$B12/MIN(6,Вводные!$B9),0) -> 0 | I27: =H27*Вводные!$B14 -> 0 | J27: =G27+I27 -> 0 | K27: =SUM($J$4:J27) -> 1.4741871e+09 | L27: =K27 -> 1.4741871e+09 | M27: =IF(AND(YEAR(B27)=YEAR(Вводные!$B$28),MONTH(B27)=MONTH(Вводные!$B$28)),L27,0) -> 0 | N27: =J27 -> 0 | O27: =IF(E27=0,0,G27/E27) -> 0 | P27: =IF(B27<Вводные!$B$28,0,IF(AND(YEAR(B27)=YEAR(Вводные!$B$28),MONTH(B27)=MONTH(Вводные!$B$28)),M27,J27)) -> 0
A28: 25 | B28: 46784 | C28: 2 | D28: =IF($A28<=Вводные!$B9,C28/SUMPRODUCT(($A$4:$A$39<=Вводные!$B9)*$C$4:$C$39),0) -> 0 | E28: =IF($A28<=Вводные!$B9,Вводные!$B11*D28,0) -> 0 | F28: =Вводные!$B13*(1+Вводные!$B15)^((A28-1)/12) -> 204120 | G28: =E28*F28 -> 0 | H28: =IF(AND($A28>=MAX(1,Вводные!$B9-MIN(6,Вводные!$B9)+1),$A28<=Вводные!$B9),Вводные!$B12/MIN(6,Вводные!$B9),0) -> 0 | I28: =H28*Вводные!$B14 -> 0 | J28: =G28+I28 -> 0 | K28: =SUM($J$4:J28) -> 1.4741871e+09 | L28: =K28 -> 1.4741871e+09 | M28: =IF(AND(YEAR(B28)=YEAR(Вводные!$B$28),MONTH(B28)=MONTH(Вводные!$B$28)),L28,0) -> 0 | N28: =J28 -> 0 | O28: =IF(E28=0,0,G28/E28) -> 0 | P28: =IF(B28<Вводные!$B$28,0,IF(AND(YEAR(B28)=YEAR(Вводные!$B$28),MONTH(B28)=MONTH(Вводные!$B$28)),M28,J28)) -> 0
A29: 26 | B29: 46813 | C29: 2 | D29: =IF($A29<=Вводные!$B9,C29/SUMPRODUCT(($A$4:$A$39<=Вводные!$B9)*$C$4:$C$39),0) -> 0 | E29: =IF($A29<=Вводные!$B9,Вводные!$B11*D29,0) -> 0 | F29: =Вводные!$B13*(1+Вводные!$B15)^((A29-1)/12) -> 205433.31 | G29: =E29*F29 -> 0 | H29: =IF(AND($A29>=MAX(1,Вводные!$B9-MIN(6,Вводные!$B9)+1),$A29<=Вводные!$B9),Вводные!$B12/MIN(6,Вводные!$B9),0) -> 0 | I29: =H29*Вводные!$B14 -> 0 | J29: =G29+I29 -> 0 | K29: =SUM($J$4:J29) -> 1.4741871e+09 | L29: =K29 -> 1.4741871e+09 | M29: =IF(AND(YEAR(B29)=YEAR(Вводные!$B$28),MONTH(B29)=MONTH(Вводные!$B$28)),L29,0) -> 0 | N29: =J29 -> 0 | O29: =IF(E29=0,0,G29/E29) -> 0 | P29: =IF(B29<Вводные!$B$28,0,IF(AND(YEAR(B29)=YEAR(Вводные!$B$28),MONTH(B29)=MONTH(Вводные!$B$28)),M29,J29)) -> 0
A30: 27 | B30: 46844 | C30: 1 | D30: =IF($A30<=Вводные!$B9,C30/SUMPRODUCT(($A$4:$A$39<=Вводные!$B9)*$C$4:$C$39),0) -> 0 | E30: =IF($A30<=Вводные!$B9,Вводные!$B11*D30,0) -> 0 | F30: =Вводные!$B13*(1+Вводные!$B15)^((A30-1)/12) -> 206755.08 | G30: =E30*F30 -> 0 | H30: =IF(AND($A30>=MAX(1,Вводные!$B9-MIN(6,Вводные!$B9)+1),$A30<=Вводные!$B9),Вводные!$B12/MIN(6,Вводные!$B9),0) -> 0 | I30: =H30*Вводные!$B14 -> 0 | J30: =G30+I30 -> 0 | K30: =SUM($J$4:J30) -> 1.4741871e+09 | L30: =K30 -> 1.4741871e+09 | M30: =IF(AND(YEAR(B30)=YEAR(Вводные!$B$28),MONTH(B30)=MONTH(Вводные!$B$28)),L30,0) -> 0 | N30: =J30 -> 0 | O30: =IF(E30=0,0,G30/E30) -> 0 | P30: =IF(B30<Вводные!$B$28,0,IF(AND(YEAR(B30)=YEAR(Вводные!$B$28),MONTH(B30)=MONTH(Вводные!$B$28)),M30,J30)) -> 0
A31: 28 | B31: 46874 | C31: 1 | D31: =IF($A31<=Вводные!$B9,C31/SUMPRODUCT(($A$4:$A$39<=Вводные!$B9)*$C$4:$C$39),0) -> 0 | E31: =IF($A31<=Вводные!$B9,Вводные!$B11*D31,0) -> 0 | F31: =Вводные!$B13*(1+Вводные!$B15)^((A31-1)/12) -> 208085.35 | G31: =E31*F31 -> 0 | H31: =IF(AND($A31>=MAX(1,Вводные!$B9-MIN(6,Вводные!$B9)+1),$A31<=Вводные!$B9),Вводные!$B12/MIN(6,Вводные!$B9),0) -> 0 | I31: =H31*Вводные!$B14 -> 0 | J31: =G31+I31 -> 0 | K31: =SUM($J$4:J31) -> 1.4741871e+09 | L31: =K31 -> 1.4741871e+09 | M31: =IF(AND(YEAR(B31)=YEAR(Вводные!$B$28),MONTH(B31)=MONTH(Вводные!$B$28)),L31,0) -> 0 | N31: =J31 -> 0 | O31: =IF(E31=0,0,G31/E31) -> 0 | P31: =IF(B31<Вводные!$B$28,0,IF(AND(YEAR(B31)=YEAR(Вводные!$B$28),MONTH(B31)=MONTH(Вводные!$B$28)),M31,J31)) -> 0
A32: 29 | B32: 46905 | C32: 1 | D32: =IF($A32<=Вводные!$B9,C32/SUMPRODUCT(($A$4:$A$39<=Вводные!$B9)*$C$4:$C$39),0) -> 0 | E32: =IF($A32<=Вводные!$B9,Вводные!$B11*D32,0) -> 0 | F32: =Вводные!$B13*(1+Вводные!$B15)^((A32-1)/12) -> 209424.17 | G32: =E32*F32 -> 0 | H32: =IF(AND($A32>=MAX(1,Вводные!$B9-MIN(6,Вводные!$B9)+1),$A32<=Вводные!$B9),Вводные!$B12/MIN(6,Вводные!$B9),0) -> 0 | I32: =H32*Вводные!$B14 -> 0 | J32: =G32+I32 -> 0 | K32: =SUM($J$4:J32) -> 1.4741871e+09 | L32: =K32 -> 1.4741871e+09 | M32: =IF(AND(YEAR(B32)=YEAR(Вводные!$B$28),MONTH(B32)=MONTH(Вводные!$B$28)),L32,0) -> 0 | N32: =J32 -> 0 | O32: =IF(E32=0,0,G32/E32) -> 0 | P32: =IF(B32<Вводные!$B$28,0,IF(AND(YEAR(B32)=YEAR(Вводные!$B$28),MONTH(B32)=MONTH(Вводные!$B$28)),M32,J32)) -> 0
A33: 30 | B33: 46935 | C33: 1 | D33: =IF($A33<=Вводные!$B9,C33/SUMPRODUCT(($A$4:$A$39<=Вводные!$B9)*$C$4:$C$39),0) -> 0 | E33: =IF($A33<=Вводные!$B9,Вводные!$B11*D33,0) -> 0 | F33: =Вводные!$B13*(1+Вводные!$B15)^((A33-1)/12) -> 210771.62 | G33: =E33*F33 -> 0 | H33: =IF(AND($A33>=MAX(1,Вводные!$B9-MIN(6,Вводные!$B9)+1),$A33<=Вводные!$B9),Вводные!$B12/MIN(6,Вводные!$B9),0) -> 0 | I33: =H33*Вводные!$B14 -> 0 | J33: =G33+I33 -> 0 | K33: =SUM($J$4:J33) -> 1.4741871e+09 | L33: =K33 -> 1.4741871e+09 | M33: =IF(AND(YEAR(B33)=YEAR(Вводные!$B$28),MONTH(B33)=MONTH(Вводные!$B$28)),L33,0) -> 0 | N33: =J33 -> 0 | O33: =IF(E33=0,0,G33/E33) -> 0 | P33: =IF(B33<Вводные!$B$28,0,IF(AND(YEAR(B33)=YEAR(Вводные!$B$28),MONTH(B33)=MONTH(Вводные!$B$28)),M33,J33)) -> 0
A34: 31 | B34: 46966 | C34: 0 | D34: =IF($A34<=Вводные!$B9,C34/SUMPRODUCT(($A$4:$A$39<=Вводные!$B9)*$C$4:$C$39),0) -> 0 | E34: =IF($A34<=Вводные!$B9,Вводные!$B11*D34,0) -> 0 | F34: =Вводные!$B13*(1+Вводные!$B15)^((A34-1)/12) -> 212127.73 | G34: =E34*F34 -> 0 | H34: =IF(AND($A34>=MAX(1,Вводные!$B9-MIN(6,Вводные!$B9)+1),$A34<=Вводные!$B9),Вводные!$B12/MIN(6,Вводные!$B9),0) -> 0 | I34: =H34*Вводные!$B14 -> 0 | J34: =G34+I34 -> 0 | K34: =SUM($J$4:J34) -> 1.4741871e+09 | L34: =K34 -> 1.4741871e+09 | M34: =IF(AND(YEAR(B34)=YEAR(Вводные!$B$28),MONTH(B34)=MONTH(Вводные!$B$28)),L34,0) -> 0 | N34: =J34 -> 0 | O34: =IF(E34=0,0,G34/E34) -> 0 | P34: =IF(B34<Вводные!$B$28,0,IF(AND(YEAR(B34)=YEAR(Вводные!$B$28),MONTH(B34)=MONTH(Вводные!$B$28)),M34,J34)) -> 0
A35: 32 | B35: 46997 | C35: 0 | D35: =IF($A35<=Вводные!$B9,C35/SUMPRODUCT(($A$4:$A$39<=Вводные!$B9)*$C$4:$C$39),0) -> 0 | E35: =IF($A35<=Вводные!$B9,Вводные!$B11*D35,0) -> 0 | F35: =Вводные!$B13*(1+Вводные!$B15)^((A35-1)/12) -> 213492.56 | G35: =E35*F35 -> 0 | H35: =IF(AND($A35>=MAX(1,Вводные!$B9-MIN(6,Вводные!$B9)+1),$A35<=Вводные!$B9),Вводные!$B12/MIN(6,Вводные!$B9),0) -> 0 | I35: =H35*Вводные!$B14 -> 0 | J35: =G35+I35 -> 0 | K35: =SUM($J$4:J35) -> 1.4741871e+09 | L35: =K35 -> 1.4741871e+09 | M35: =IF(AND(YEAR(B35)=YEAR(Вводные!$B$28),MONTH(B35)=MONTH(Вводные!$B$28)),L35,0) -> 0 | N35: =J35 -> 0 | O35: =IF(E35=0,0,G35/E35) -> 0 | P35: =IF(B35<Вводные!$B$28,0,IF(AND(YEAR(B35)=YEAR(Вводные!$B$28),MONTH(B35)=MONTH(Вводные!$B$28)),M35,J35)) -> 0
A36: 33 | B36: 47027 | C36: 0 | D36: =IF($A36<=Вводные!$B9,C36/SUMPRODUCT(($A$4:$A$39<=Вводные!$B9)*$C$4:$C$39),0) -> 0 | E36: =IF($A36<=Вводные!$B9,Вводные!$B11*D36,0) -> 0 | F36: =Вводные!$B13*(1+Вводные!$B15)^((A36-1)/12) -> 214866.18 | G36: =E36*F36 -> 0 | H36: =IF(AND($A36>=MAX(1,Вводные!$B9-MIN(6,Вводные!$B9)+1),$A36<=Вводные!$B9),Вводные!$B12/MIN(6,Вводные!$B9),0) -> 0 | I36: =H36*Вводные!$B14 -> 0 | J36: =G36+I36 -> 0 | K36: =SUM($J$4:J36) -> 1.4741871e+09 | L36: =K36 -> 1.4741871e+09 | M36: =IF(AND(YEAR(B36)=YEAR(Вводные!$B$28),MONTH(B36)=MONTH(Вводные!$B$28)),L36,0) -> 0 | N36: =J36 -> 0 | O36: =IF(E36=0,0,G36/E36) -> 0 | P36: =IF(B36<Вводные!$B$28,0,IF(AND(YEAR(B36)=YEAR(Вводные!$B$28),MONTH(B36)=MONTH(Вводные!$B$28)),M36,J36)) -> 0
A37: 34 | B37: 47058 | C37: 0 | D37: =IF($A37<=Вводные!$B9,C37/SUMPRODUCT(($A$4:$A$39<=Вводные!$B9)*$C$4:$C$39),0) -> 0 | E37: =IF($A37<=Вводные!$B9,Вводные!$B11*D37,0) -> 0 | F37: =Вводные!$B13*(1+Вводные!$B15)^((A37-1)/12) -> 216248.64 | G37: =E37*F37 -> 0 | H37: =IF(AND($A37>=MAX(1,Вводные!$B9-MIN(6,Вводные!$B9)+1),$A37<=Вводные!$B9),Вводные!$B12/MIN(6,Вводные!$B9),0) -> 0 | I37: =H37*Вводные!$B14 -> 0 | J37: =G37+I37 -> 0 | K37: =SUM($J$4:J37) -> 1.4741871e+09 | L37: =K37 -> 1.4741871e+09 | M37: =IF(AND(YEAR(B37)=YEAR(Вводные!$B$28),MONTH(B37)=MONTH(Вводные!$B$28)),L37,0) -> 0 | N37: =J37 -> 0 | O37: =IF(E37=0,0,G37/E37) -> 0 | P37: =IF(B37<Вводные!$B$28,0,IF(AND(YEAR(B37)=YEAR(Вводные!$B$28),MONTH(B37)=MONTH(Вводные!$B$28)),M37,J37)) -> 0
A38: 35 | B38: 47088 | C38: 0 | D38: =IF($A38<=Вводные!$B9,C38/SUMPRODUCT(($A$4:$A$39<=Вводные!$B9)*$C$4:$C$39),0) -> 0 | E38: =IF($A38<=Вводные!$B9,Вводные!$B11*D38,0) -> 0 | F38: =Вводные!$B13*(1+Вводные!$B15)^((A38-1)/12) -> 217639.99 | G38: =E38*F38 -> 0 | H38: =IF(AND($A38>=MAX(1,Вводные!$B9-MIN(6,Вводные!$B9)+1),$A38<=Вводные!$B9),Вводные!$B12/MIN(6,Вводные!$B9),0) -> 0 | I38: =H38*Вводные!$B14 -> 0 | J38: =G38+I38 -> 0 | K38: =SUM($J$4:J38) -> 1.4741871e+09 | L38: =K38 -> 1.4741871e+09 | M38: =IF(AND(YEAR(B38)=YEAR(Вводные!$B$28),MONTH(B38)=MONTH(Вводные!$B$28)),L38,0) -> 0 | N38: =J38 -> 0 | O38: =IF(E38=0,0,G38/E38) -> 0 | P38: =IF(B38<Вводные!$B$28,0,IF(AND(YEAR(B38)=YEAR(Вводные!$B$28),MONTH(B38)=MONTH(Вводные!$B$28)),M38,J38)) -> 0
A39: 36 | B39: 47119 | C39: 0 | D39: =IF($A39<=Вводные!$B9,C39/SUMPRODUCT(($A$4:$A$39<=Вводные!$B9)*$C$4:$C$39),0) -> 0 | E39: =IF($A39<=Вводные!$B9,Вводные!$B11*D39,0) -> 0 | F39: =Вводные!$B13*(1+Вводные!$B15)^((A39-1)/12) -> 219040.29 | G39: =E39*F39 -> 0 | H39: =IF(AND($A39>=MAX(1,Вводные!$B9-MIN(6,Вводные!$B9)+1),$A39<=Вводные!$B9),Вводные!$B12/MIN(6,Вводные!$B9),0) -> 0 | I39: =H39*Вводные!$B14 -> 0 | J39: =G39+I39 -> 0 | K39: =SUM($J$4:J39) -> 1.4741871e+09 | L39: =K39 -> 1.4741871e+09 | M39: =IF(AND(YEAR(B39)=YEAR(Вводные!$B$28),MONTH(B39)=MONTH(Вводные!$B$28)),L39,0) -> 0 | N39: =J39 -> 0 | O39: =IF(E39=0,0,G39/E39) -> 0 | P39: =IF(B39<Вводные!$B$28,0,IF(AND(YEAR(B39)=YEAR(Вводные!$B$28),MONTH(B39)=MONTH(Вводные!$B$28)),M39,J39)) -> 0
A41: ИТОГО | E41: =SUM(E4:E39) -> 7860.32 | J41: =SUM(J4:J39) -> 1.4741871e+09 | K41: =MAX(K4:K39) -> 1.4741871e+09 | L41: =MAX(L4:L39) -> 1.4741871e+09 | N41: =SUM(N4:N39) -> 1.4741871e+09

Sheet Кредит
A1: КРЕДИТ И ПРОЦЕНТЫ
A3: Месяц | B3: Дата | C3: Лимит периода | D3: CAPEX | E3: Коммерч. расходы | F3: Всего затрат | G3: Собств. средства | H3: Потребность в кредите | I3: Выборка | J3: Долг на начало | K3: Эскроу накопленно | L3: Коэфф. покрытия | M3: Ставка, годовая | N3: Начисленные проценты | O3: Капитализация процентов | P3: Проценты к оплате | Q3: Комиссия за лимит | R3: Погашение основного долга | S3: Долг на конец | T3: Комментарий | V3: Ключевые метрики
A4: 1 | B4: 46054 | C4: =IF(B4<=DATE(2026,3,31),159641000,IF(B4<=DATE(2026,12,31),545820000,IF(B4<=DATE(2027,6,30),797820000,IF(B4<=DATE(2028,3,31),1084000000,1084000000)))) -> 159641000 | D4: =ГПР!F16 -> 14148576 | E4: =ГПР!F14 -> 7074288 | F4: =IF(A4<=Вводные!$B9,Структура_затрат!$H$35/Вводные!$B9,0) -> 2764100.8 | G4: =(E4+F4)*Вводные!$B18 -> 1478709.8 | H4: =MAX(0,E4+F4-G4) -> 8359679 | I4: =MIN(H4,MAX(0,C4-J4)) -> 8359679 | J4: =IF(A4=1,0,S3) -> 0 | K4: =Продажи!L4 -> 26453000 | L4: =IF((J4+I4)=0,0,K4/(J4+I4)) -> 3.164356 | M4: =IF(L4>1.3,Вводные!$B26,IF(L4>1.2,Вводные!$B25,IF(L4>1.1,Вводные!$B24,IF(L4>=1,Вводные!$B23,Вводные!$B21+Вводные!$B22)))) -> 0.0001 | N4: =(J4+I4)*M4/12 -> 69.663991 | O4: =IF(B4<=Вводные!$B27,N4,0) -> 69.663991 | P4: =IF(B4<=Вводные!$B27,0,N4) -> 0 | Q4: =MAX(0,(C4-(J4+I4)))*Вводные!$B20/12 -> 36559.653 | R4: =IF(OR(YEAR(B4)>YEAR(Вводные!$B28),AND(YEAR(B4)=YEAR(Вводные!$B28),MONTH(B4)>=MONTH(Вводные!$B28))),MAX(0,MIN(J4+I4+O4+Q4,Продажи!N4-P4-Q4)),0) -> 0 | S4: =J4+I4+O4+Q4-R4 -> 8396308.3 | T4: =IF(S4=0,"Кредит погашен",IF(L4<1,"Низкое покрытие","Рабочий режим")) -> Рабочий режим | V4: Пик долга | W4: =MAX(S4:S39) -> 7.4105582e+08
A5: 2 | B5: 46082 | C5: =IF(B5<=DATE(2026,3,31),159641000,IF(B5<=DATE(2026,12,31),545820000,IF(B5<=DATE(2027,6,30),797820000,IF(B5<=DATE(2028,3,31),1084000000,1084000000)))) -> 159641000 | D5: =ГПР!G16 -> 33580116 | E5: =ГПР!G14 -> 16790058 | F5: =IF(A5<=Вводные!$B9,Структура_затрат!$H$35/Вводные!$B9,0) -> 2764100.8 | G5: =(E5+F5)*Вводные!$B18 -> 2938990.1 | H5: =MAX(0,E5+F5-G5) -> 16615169 | I5: =MIN(H5,MAX(0,C5-J5)) -> 16615169 | J5: =IF(A5=1,0,S4) -> 8396308.3 | K5: =Продажи!L5 -> 53076199 | L5: =IF((J5+I5)=0,0,K5/(J5+I5)) -> 2.1220738 | M5: =IF(L5>1.3,Вводные!$B26,IF(L5>1.2,Вводные!$B25,IF(L5>1.1,Вводные!$B24,IF(L5>=1,Вводные!$B23,Вводные!$B21+Вводные!$B22)))) -> 0.0001 | N5: =(J5+I5)*M5/12 -> 208.42898 | O5: =IF(B5<=Вводные!$B27,N5,0) -> 208.42898 | P5: =IF(B5<=Вводные!$B27,0,N5) -> 0 | Q5: =MAX(0,(C5-(J5+I5)))*Вводные!$B20/12 -> 32535.468 | R5: =IF(OR(YEAR(B5)>YEAR(Вводные!$B28),AND(YEAR(B5)=YEAR(Вводные!$B28),MONTH(B5)>=MONTH(Вводные!$B28))),MAX(0,MIN(J5+I5+O5+Q5,Продажи!N5-P5-Q5)),0) -> 0 | S5: =J5+I5+O5+Q5-R5 -> 25044221 | T5: =IF(S5=0,"Кредит погашен",IF(L5<1,"Низкое покрытие","Рабочий режим")) -> Рабочий режим | V5: Капитализированные % | W5: =SUM(O4:O39) -> 324945.55
A6: 3 | B6: 46113 | C6: =IF(B6<=DATE(2026,3,31),159641000,IF(B6<=DATE(2026,12,31),545820000,IF(B6<=DATE(2027,6,30),797820000,IF(B6<=DATE(2028,3,31),1084000000,1084000000)))) -> 545820000 | D6: =ГПР!H16 -> 74487570 | E6: =ГПР!H14 -> 37243785 | F6: =IF(A6<=Вводные!$B9,Структура_затрат!$H$35/Вводные!$B9,0) -> 2764100.8 | G6: =(E6+F6)*Вводные!$B18 -> 6013185.2 | H6: =MAX(0,E6+F6-G6) -> 33994701 | I6: =MIN(H6,MAX(0,C6-J6)) -> 33994701 | J6: =IF(A6=1,0,S5) -> 25044221 | K6: =Продажи!L6 -> 79870693 | L6: =IF((J6+I6)=0,0,K6/(J6+I6)) -> 1.3528481 | M6: =IF(L6>1.3,Вводные!$B26,IF(L6>1.2,Вводные!$B25,IF(L6>1.1,Вводные!$B24,IF(L6>=1,Вводные!$B23,Вводные!$B21+Вводные!$B22)))) -> 0.0001 | N6: =(J6+I6)*M6/12 -> 491.99101 | O6: =IF(B6<=Вводные!$B27,N6,0) -> 491.99101 | P6: =IF(B6<=Вводные!$B27,0,N6) -> 0 | Q6: =MAX(0,(C6-(J6+I6)))*Вводные!$B20/12 -> 117638.76 | R6: =IF(OR(YEAR(B6)>YEAR(Вводные!$B28),AND(YEAR(B6)=YEAR(Вводные!$B28),MONTH(B6)>=MONTH(Вводные!$B28))),MAX(0,MIN(J6+I6+O6+Q6,Продажи!N6-P6-Q6)),0) -> 0 | S6: =J6+I6+O6+Q6-R6 -> 59157052 | T6: =IF(S6=0,"Кредит погашен",IF(L6<1,"Низкое покрытие","Рабочий режим")) -> Рабочий режим | V6: Проценты к оплате | W6: =SUM(P4:P39) -> 111040.08
A7: 4 | B7: 46143 | C7: =IF(B7<=DATE(2026,3,31),159641000,IF(B7<=DATE(2026,12,31),545820000,IF(B7<=DATE(2027,6,30),797820000,IF(B7<=DATE(2028,3,31),1084000000,1084000000)))) -> 545820000 | D7: =ГПР!I16 -> 55056030 | E7: =ГПР!I14 -> 27528015 | F7: =IF(A7<=Вводные!$B9,Структура_затрат!$H$35/Вводные!$B9,0) -> 2764100.8 | G7: =(E7+F7)*Вводные!$B18 -> 4552905 | H7: =MAX(0,E7+F7-G7) -> 25739211 | I7: =MIN(H7,MAX(0,C7-J7)) -> 25739211 | J7: =IF(A7=1,0,S6) -> 59157052 | K7: =Продажи!L7 -> 1.0683758e+08 | L7: =IF((J7+I7)=0,0,K7/(J7+I7)) -> 1.2584486 | M7: =IF(L7>1.3,Вводные!$B26,IF(L7>1.2,Вводные!$B25,IF(L7>1.1,Вводные!$B24,IF(L7>=1,Вводные!$B23,Вводные!$B21+Вводные!$B22)))) -> 0.0151 | N7: =(J7+I7)*M7/12 -> 106827.8 | O7: =IF(B7<=Вводные!$B27,N7,0) -> 106827.8 | P7: =IF(B7<=Вводные!$B27,0,N7) -> 0 | Q7: =MAX(0,(C7-(J7+I7)))*Вводные!$B20/12 -> 111389.9 | R7: =IF(OR(YEAR(B7)>YEAR(Вводные!$B28),AND(YEAR(B7)=YEAR(Вводные!$B28),MONTH(B7)>=MONTH(Вводные!$B28))),MAX(0,MIN(J7+I7+O7+Q7,Продажи!N7-P7-Q7)),0) -> 0 | S7: =J7+I7+O7+Q7-R7 -> 85114481 | T7: =IF(S7=0,"Кредит погашен",IF(L7<1,"Низкое покрытие","Рабочий режим")) -> Рабочий режим | V7: Комиссия | W7: =SUM(Q4:Q39) -> 2586099.3
A8: 5 | B8: 46174 | C8: =IF(B8<=DATE(2026,3,31),159641000,IF(B8<=DATE(2026,12,31),545820000,IF(B8<=DATE(2027,6,30),797820000,IF(B8<=DATE(2028,3,31),1084000000,1084000000)))) -> 545820000 | D8: =ГПР!J16 -> 1.0279525e+08 | E8: =ГПР!J14 -> 51397623 | F8: =IF(A8<=Вводные!$B9,Структура_затрат!$H$35/Вводные!$B9,0) -> 2764100.8 | G8: =(E8+F8)*Вводные!$B18 -> 8140507.1 | H8: =MAX(0,E8+F8-G8) -> 46021217 | I8: =MIN(H8,MAX(0,C8-J8)) -> 46021217 | J8: =IF(A8=1,0,S7) -> 85114481 | K8: =Продажи!L8 -> 1.6111838e+08 | L8: =IF((J8+I8)=0,0,K8/(J8+I8)) -> 1.2286386 | M8: =IF(L8>1.3,Вводные!$B26,IF(L8>1.2,Вводные!$B25,IF(L8>1.1,Вводные!$B24,IF(L8>=1,Вводные!$B23,Вводные!$B21+Вводные!$B22)))) -> 0.0151 | N8: =(J8+I8)*M8/12 -> 165012.42 | O8: =IF(B8<=Вводные!$B27,N8,0) -> 165012.42 | P8: =IF(B8<=Вводные!$B27,0,N8) -> 0 | Q8: =MAX(0,(C8-(J8+I8)))*Вводные!$B20/12 -> 100215.37 | R8: =IF(OR(YEAR(B8)>YEAR(Вводные!$B28),AND(YEAR(B8)=YEAR(Вводные!$B28),MONTH(B8)>=MONTH(Вводные!$B28))),MAX(0,MIN(J8+I8+O8+Q8,Продажи!N8-P8-Q8)),0) -> 0 | S8: =J8+I8+O8+Q8-R8 -> 1.3140093e+08 | T8: =IF(S8=0,"Кредит погашен",IF(L8<1,"Низкое покрытие","Рабочий режим")) -> Рабочий режим | V8: Остаток долга | W8: =S39 -> 7.4105582e+08
A9: 6 | B9: 46204 | C9: =IF(B9<=DATE(2026,3,31),159641000,IF(B9<=DATE(2026,12,31),545820000,IF(B9<=DATE(2027,6,30),797820000,IF(B9<=DATE(2028,3,31),1084000000,1084000000)))) -> 545820000 | D9: =ГПР!K16 -> 47739216 | E9: =ГПР!K14 -> 23869608 | F9: =IF(A9<=Вводные!$B9,Структура_затрат!$H$35/Вводные!$B9,0) -> 2764100.8 | G9: =(E9+F9)*Вводные!$B18 -> 4003046.4 | H9: =MAX(0,E9+F9-G9) -> 22630662 | I9: =MIN(H9,MAX(0,C9-J9)) -> 22630662 | J9: =IF(A9=1,0,S8) -> 1.3140093e+08 | K9: =Продажи!L9 -> 2.1574841e+08 | L9: =IF((J9+I9)=0,0,K9/(J9+I9)) -> 1.4006764 | M9: =IF(L9>1.3,Вводные!$B26,IF(L9>1.2,Вводные!$B25,IF(L9>1.1,Вводные!$B24,IF(L9>=1,Вводные!$B23,Вводные!$B21+Вводные!$B22)))) -> 0.0001 | N9: =(J9+I9)*M9/12 -> 1283.5966 | O9: =IF(B9<=Вводные!$B27,N9,0) -> 1283.5966 | P9: =IF(B9<=Вводные!$B27,0,N9) -> 0 | Q9: =MAX(0,(C9-(J9+I9)))*Вводные!$B20/12 -> 94682.2 | R9: =IF(OR(YEAR(B9)>YEAR(Вводные!$B28),AND(YEAR(B9)=YEAR(Вводные!$B28),MONTH(B9)>=MONTH(Вводные!$B28))),MAX(0,MIN(J9+I9+O9+Q9,Продажи!N9-P9-Q9)),0) -> 0 | S9: =J9+I9+O9+Q9-R9 -> 1.5412755e+08 | T9: =IF(S9=0,"Кредит погашен",IF(L9<1,"Низкое покрытие","Рабочий режим")) -> Рабочий режим
A10: 7 | B10: 46235 | C10: =IF(B10<=DATE(2026,3,31),159641000,IF(B10<=DATE(2026,12,31),545820000,IF(B10<=DATE(2027,6,30),797820000,IF(B10<=DATE(2028,3,31),1084000000,1084000000)))) -> 545820000 | D10: =ГПР!L16 -> 47739216 | E10: =ГПР!L14 -> 23869608 | F10: =IF(A10<=Вводные!$B9,Структура_затрат!$H$35/Вводные!$B9,0) -> 2764100.8 | G10: =(E10+F10)*Вводные!$B18 -> 4003046.4 | H10: =MAX(0,E10+F10-G10) -> 22630662 | I10: =MIN(H10,MAX(0,C10-J10)) -> 22630662 | J10: =IF(A10=1,0,S9) -> 1.5412755e+08 | K10: =Продажи!L10 -> 2.982207e+08 | L10: =IF((J10+I10)=0,0,K10/(J10+I10)) -> 1.6871674 | M10: =IF(L10>1.3,Вводные!$B26,IF(L10>1.2,Вводные!$B25,IF(L10>1.1,Вводные!$B24,IF(L10>=1,Вводные!$B23,Вводные!$B21+Вводные!$B22)))) -> 0.0001 | N10: =(J10+I10)*M10/12 -> 1472.9851 | O10: =IF(B10<=Вводные!$B27,N10,0) -> 1472.9851 | P10: =IF(B10<=Вводные!$B27,0,N10) -> 0 | Q10: =MAX(0,(C10-(J10+I10)))*Вводные!$B20/12 -> 89189.931 | R10: =IF(OR(YEAR(B10)>YEAR(Вводные!$B28),AND(YEAR(B10)=YEAR(Вводные!$B28),MONTH(B10)>=MONTH(Вводные!$B28))),MAX(0,MIN(J10+I10+O10+Q10,Продажи!N10-P10-Q10)),0) -> 0 | S10: =J10+I10+O10+Q10-R10 -> 1.7684888e+08 | T10: =IF(S10=0,"Кредит погашен",IF(L10<1,"Низкое покрытие","Рабочий режим")) -> Рабочий режим
A11: 8 | B11: 46266 | C11: =IF(B11<=DATE(2026,3,31),159641000,IF(B11<=DATE(2026,12,31),545820000,IF(B11<=DATE(2027,6,30),797820000,IF(B11<=DATE(2028,3,31),1084000000,1084000000)))) -> 545820000 | D11: =ГПР!M16 -> 47739216 | E11: =ГПР!M14 -> 23869608 | F11: =IF(A11<=Вводные!$B9,Структура_затрат!$H$35/Вводные!$B9,0) -> 2764100.8 | G11: =(E11+F11)*Вводные!$B18 -> 4003046.4 | H11: =MAX(0,E11+F11-G11) -> 22630662 | I11: =MIN(H11,MAX(0,C11-J11)) -> 22630662 | J11: =IF(A11=1,0,S10) -> 1.7684888e+08 | K11: =Продажи!L11 -> 3.8122363e+08 | L11: =IF((J11+I11)=0,0,K11/(J11+I11)) -> 1.9110914 | M11: =IF(L11>1.3,Вводные!$B26,IF(L11>1.2,Вводные!$B25,IF(L11>1.1,Вводные!$B24,IF(L11>=1,Вводные!$B23,Вводные!$B21+Вводные!$B22)))) -> 0.0001 | N11: =(J11+I11)*M11/12 -> 1662.3295 | O11: =IF(B11<=Вводные!$B27,N11,0) -> 1662.3295 | P11: =IF(B11<=Вводные!$B27,0,N11) -> 0 | Q11: =MAX(0,(C11-(J11+I11)))*Вводные!$B20/12 -> 83698.944 | R11: =IF(OR(YEAR(B11)>YEAR(Вводные!$B28),AND(YEAR(B11)=YEAR(Вводные!$B28),MONTH(B11)>=MONTH(Вводные!$B28))),MAX(0,MIN(J11+I11+O11+Q11,Продажи!N11-P11-Q11)),0) -> 0 | S11: =J11+I11+O11+Q11-R11 -> 1.995649e+08 | T11: =IF(S11=0,"Кредит погашен",IF(L11<1,"Низкое покрытие","Рабочий режим")) -> Рабочий режим
A12: 9 | B12: 46296 | C12: =IF(B12<=DATE(2026,3,31),159641000,IF(B12<=DATE(2026,12,31),545820000,IF(B12<=DATE(2027,6,30),797820000,IF(B12<=DATE(2028,3,31),1084000000,1084000000)))) -> 545820000 | D12: =ГПР!N16 -> 1.6257036e+08 | E12: =ГПР!N14 -> 81285182 | F12: =IF(A12<=Вводные!$B9,Структура_затрат!$H$35/Вводные!$B9,0) -> 2764100.8 | G12: =(E12+F12)*Вводные!$B18 -> 12632607 | H12: =MAX(0,E12+F12-G12) -> 71416676 | I12: =MIN(H12,MAX(0,C12-J12)) -> 71416676 | J12: =IF(A12=1,0,S11) -> 1.995649e+08 | K12: =Продажи!L12 -> 4.9260625e+08 | L12: =IF((J12+I12)=0,0,K12/(J12+I12)) -> 1.8178588 | M12: =IF(L12>1.3,Вводные!$B26,IF(L12>1.2,Вводные!$B25,IF(L12>1.1,Вводные!$B24,IF(L12>=1,Вводные!$B23,Вводные!$B21+Вводные!$B22)))) -> 0.0001 | N12: =(J12+I12)*M12/12 -> 2258.1798 | O12: =IF(B12<=Вводные!$B27,N12,0) -> 2258.1798 | P12: =IF(B12<=Вводные!$B27,0,N12) -> 0 | Q12: =MAX(0,(C12-(J12+I12)))*Вводные!$B20/12 -> 66419.286 | R12: =IF(OR(YEAR(B12)>YEAR(Вводные!$B28),AND(YEAR(B12)=YEAR(Вводные!$B28),MONTH(B12)>=MONTH(Вводные!$B28))),MAX(0,MIN(J12+I12+O12+Q12,Продажи!N12-P12-Q12)),0) -> 0 | S12: =J12+I12+O12+Q12-R12 -> 2.7105025e+08 | T12: =IF(S12=0,"Кредит погашен",IF(L12<1,"Низкое покрытие","Рабочий режим")) -> Рабочий режим
A13: 10 | B13: 46327 | C13: =IF(B13<=DATE(2026,3,31),159641000,IF(B13<=DATE(2026,12,31),545820000,IF(B13<=DATE(2027,6,30),797820000,IF(B13<=DATE(2028,3,31),1084000000,1084000000)))) -> 545820000 | D13: =ГПР!O16 -> 1.7197655e+08 | E13: =ГПР!O14 -> 85988273 | F13: =IF(A13<=Вводные!$B9,Структура_затрат!$H$35/Вводные!$B9,0) -> 2764100.8 | G13: =(E13+F13)*Вводные!$B18 -> 13339482 | H13: =MAX(0,E13+F13-G13) -> 75412892 | I13: =MIN(H13,MAX(0,C13-J13)) -> 75412892 | J13: =IF(A13=1,0,S12) -> 2.7105025e+08 | K13: =Продажи!L13 -> 6.047055e+08 | L13: =IF((J13+I13)=0,0,K13/(J13+I13)) -> 1.7453675 | M13: =IF(L13>1.3,Вводные!$B26,IF(L13>1.2,Вводные!$B25,IF(L13>1.1,Вводные!$B24,IF(L13>=1,Вводные!$B23,Вводные!$B21+Вводные!$B22)))) -> 0.0001 | N13: =(J13+I13)*M13/12 -> 2887.1929 | O13: =IF(B13<=Вводные!$B27,N13,0) -> 2887.1929 | P13: =IF(B13<=Вводные!$B27,0,N13) -> 0 | Q13: =MAX(0,(C13-(J13+I13)))*Вводные!$B20/12 -> 48177.906 | R13: =IF(OR(YEAR(B13)>YEAR(Вводные!$B28),AND(YEAR(B13)=YEAR(Вводные!$B28),MONTH(B13)>=MONTH(Вводные!$B28))),MAX(0,MIN(J13+I13+O13+Q13,Продажи!N13-P13-Q13)),0) -> 0 | S13: =J13+I13+O13+Q13-R13 -> 3.4651421e+08 | T13: =IF(S13=0,"Кредит погашен",IF(L13<1,"Низкое покрытие","Рабочий режим")) -> Рабочий режим
